<robot name="carl">

  <link name="base_link">
   <visual>
      <origin xyz="0 0 0" rpy="0 0 0"/>    
      <geometry>
        <mesh filename="package://carl_description/meshes/FullRobot_-_RMP_210-1_RMP_Powerbase-1.STL" />
      </geometry>
    </visual>
    <collision>
      <origin xyz="0 0 0" rpy="0 0 0"/> 
      <geometry> 
        <mesh filename="package://carl_description/meshes/FullRobot_-_RMP_210-1_RMP_Powerbase-1.STL"/>
      </geometry>
    </collision>
  </link>
  
  <link name="LeftWheel_link">
    <visual>
      <origin xyz="0 0.02 -0.32" rpy="1.5708 0 0" />
      <geometry>
        <mesh filename="package://carl_description/meshes/FullRobot_-_RMP_210-1_StandardWheel-2.STL" />
      </geometry>
    </visual>
    <collision>
      <origin xyz="0 0.02 -0.32" rpy="1.5708 0 0" />
      <geometry>
        <mesh filename="package://carl_description/meshes/FullRobot_-_RMP_210-1_StandardWheel-2.STL"/>
      </geometry>
    </collision>
  </link>
  
  <link name="RightWheel_link">
    <visual>
     <origin xyz="0 -0.02 -0.32" rpy="-1.5708 0 0" />
      <geometry>
        <mesh filename="package://carl_description/meshes/FullRobot_-_RMP_210-1_StandardWheel-1.STL" />
      </geometry>
    </visual>
    <collision>
      <origin xyz="0 -0.02 -0.32" rpy="-1.5708 0 0" />
      <geometry>
        <mesh filename="package://carl_description/meshes/FullRobot_-_RMP_210-1_StandardWheel-1.STL"/>
      </geometry>
    </collision>
  </link>

  <link name="Caster_link">
    <visual>
      <origin xyz="0 0 0" rpy="0 0 0"/>
      <geometry>
        <mesh filename="package://carl_description/meshes/FullRobot_-_RMP_210-1_CasterAssembly-1.STL" />
      </geometry>
    </visual>
    <collision>
      <origin xyz="0 0 0" rpy="0 0 0"/>
      <geometry>
        <mesh filename="package://carl_description/meshes/FullRobot_-_RMP_210-1_CasterAssembly-1.STL"/>
      </geometry>
    </collision>
  </link>
  
  <link name="RearLeftStrut_link">
    <visual>
      <origin xyz="0.19 -0.20 -0.22" rpy="0 0 0" />
      <geometry>
        <mesh filename="package://carl_description/meshes/FullRobot_-_SuperStructure-1_RearVerticalStrut-1.STL" />
      </geometry>
    </visual>
    <collision>
	  <origin xyz="0.19 -0.20 -0.22" rpy="0 0 0" />
      <geometry>
        <mesh filename="package://carl_description/meshes/FullRobot_-_SuperStructure-1_RearVerticalStrut-1.STL"/>
      </geometry>
    </collision>
  </link>
  
  <link name="RearRightStrut_link">
    <visual>
      <origin xyz="0.19 0.20 -0.22" rpy="0 0 0" />
      <geometry>
        <mesh filename="package://carl_description/meshes/FullRobot_-_SuperStructure-1_RearVerticalStrut-2.STL" />
      </geometry>
    </visual>
    <collision>
      <origin xyz="0.19 0.20 -0.22" rpy="0 0 0" />
      <geometry>
        <mesh filename="package://carl_description/meshes/FullRobot_-_SuperStructure-1_RearVerticalStrut-2.STL"/>
      </geometry>
    </collision>
  </link>

  <link name="TopPlate_link">
    <visual>
      <origin xyz="-.11 0 -0.52" rpy="0 0 0" />
      <geometry>
        <mesh filename="package://carl_description/meshes/FullRobot_-_SuperStructure-1_Table_Plate-1.STL" />
      </geometry>
    </visual>
    <collision>
      <origin xyz="-.11 0 -0.52" rpy="0 0 0" />
      <geometry>
        <mesh filename="package://carl_description/meshes/FullRobot_-_SuperStructure-1_Table_Plate-1.STL"/>
      </geometry>
    </collision>
  </link>
  
  <link name="CameraLift_link">
    <visual>
      <origin xyz="0.22 0 -1.36" rpy="0 0 0" />
      <geometry>
        <mesh filename="package://carl_description/meshes/FullRobot_-_tempHorizontal-1.STL" />
      </geometry>
    </visual>
    <collision>
      <origin xyz="0.22 0 -1.36" rpy="0 0 0" />
      <geometry> 	
        <mesh filename="package://carl_description/meshes/FullRobot_-_tempHorizontal-1.STL"/>
      </geometry>
    </collision>
  </link>
  
    <link name="CameraTiltBracket_link">
    <!--<visual>
      <origin xyz="0 0 0" rpy="0 0 0"/>
      <geometry>
        <mesh filename="package://carl_description/meshes/FullRobot_-_tempSwivelMount-1.STL" />
      </geometry>
    </visual>-->
    <collision>
      <origin xyz="0 0 0" rpy="0 0 0"/>
      <geometry>
        <mesh filename="package://carl_description/meshes/FullRobot_-_tempSwivelMount-1.STL"/>
      </geometry>
    </collision>
  </link>
  
  <link name="CameraTiltPlate_link">
    <visual>
      <origin xyz="-1.24 .54 0 " rpy="-1.5708 0 -2.1" />
      <geometry>
        <mesh filename="package://carl_description/meshes/FullRobot_-_tempPlate-1.STL" />
      </geometry>
    </visual>
    <collision>
      <origin xyz="-1.24 .54 0 " rpy="-1.5708 0 -2.1" />
      <geometry>
        <mesh filename="package://carl_description/meshes/FullRobot_-_tempPlate-1.STL"/>
      </geometry>
    </collision>
  </link>
  
  <link name="JacoMount_link">
    <visual>      
      <origin xyz="-0.33 0 -0.35" rpy="0 0 0" />
      <geometry>
        <mesh filename="package://carl_description/meshes/FullRobot_-_SuperStructure-1_ArmMountHoriz-1.STL" />
      </geometry>
    </visual>
    <collision>
      <origin xyz="-0.33 0 -0.35" rpy="0 0 0" />
      <geometry>
        <mesh filename="package://carl_description/meshes/FullRobot_-_SuperStructure-1_ArmMountHoriz-1.STL"/>
      </geometry>
    </collision>
  </link>

  <link name="Hokuyo_link">
    <visual>
      <origin xyz="-0.36 0 0" rpy="0 0 0" />
      <geometry>
        <mesh filename="package://carl_description/meshes/FullRobot_-_hokuyo-1.STL" />
      </geometry>
    </visual>
    <collision>
      <origin xyz="-0.36 0 0" rpy="0 0 0" />
      <geometry>
        <mesh filename="package://carl_description/meshes/FullRobot_-_hokuyo-1.STL"/>
      </geometry>
    </collision>
  </link>

  <joint name="BaseToLeftWheel" type="continuous">
    <parent link="base_link"/>
    <child link="LeftWheel_link"/>
    <origin xyz="0.02 0.32 0" rpy="-1.5708 0 0" />
    <axis xyz="0 0 1" />
  </joint>
  
  <joint name="BaseToRightWheel" type="continuous">
    <parent link="base_link"/>
    <child link="RightWheel_link"/>
    <origin xyz="0.02 -0.32 0" rpy="1.5708 0 0" />
    <axis xyz="0 0 1" />
  </joint>
  
  <joint name="BaseToCaster" type="fixed">
    <parent link="base_link"/>
    <child link="Caster_link"/>
    <origin xyz="0 0 0" rpy="0 0 0" />
  </joint>

  <joint name="BaseToRearLeftStrut" type="fixed">
    <parent link="base_link"/>
    <child link="RearLeftStrut_link"/>
    <origin xyz="-0.19 0.20 0.22" rpy="0 0 0" />
  </joint>

  <joint name="BaseToRearRightStrut" type="fixed">
    <parent link="base_link"/>
    <child link="RearRightStrut_link"/>
    <origin xyz="-0.19 -0.20 0.22" rpy="0 0 0" />
  </joint>

  <joint name="RearLeftStrutToTopPlate" type="fixed">
    <parent link="RearRightStrut_link"/>
    <child link="TopPlate_link"/>
    <origin xyz="0.30 0.20 0.30" rpy="0 0 0" />
  </joint>
  
  <joint name="RearLeftStrutToCameraLift" type="fixed">
    <parent link="RearRightStrut_link"/>
    <child link="CameraLift_link"/>
    <origin xyz="0.01 0.20 1.17" rpy="0 0 0" />
  </joint>
  
    <joint name="CameraLiftToCameraTiltBracket" type="continuous">
    <parent link="CameraLift_link"/>
    <child link="CameraTiltBracket_link"/>
    <origin xyz="0.03 -0.10 0" rpy="1.5708 0 0" />
    <axis xyz="0 0 1" />
  </joint>
  
  <joint name="CameraLiftBracketToCameraTiltPlate" type="fixed">
    <parent link="CameraTiltBracket_link"/>
    <child link="CameraTiltPlate_link"/>
    <origin xyz="0.11 0 -0.10" rpy="0 0 0" />
  </joint>

  <joint name="TopPlateToJacoMount" type="fixed">
    <parent link="TopPlate_link"/>
    <child link="JacoMount_link"/>
    <origin xyz="0.216 0 -0.13" rpy="0 0 0" />
  </joint>

  <joint name="CasterToHokuyo" type="fixed">
    <parent link="Caster_link"/>
    <child link="Hokuyo_link"/>
    <origin xyz="0.36 0 0" rpy="0 0 0" />
  </joint>

</robot>
