<?xml version="1.0" ?>
<!-- =================================================================================== -->
<!-- |    This document was autogenerated by xacro from carl.xacro                     | -->
<!-- |    EDITING THIS FILE BY HAND IS NOT RECOMMENDED                                 | -->
<!-- =================================================================================== -->
<robot name="carl" xmlns:body="http://playerstage.sourceforge.net/gazebo/xmlschema/#body" xmlns:controller="http://playerstage.sourceforge.net/gazebo/xmlschema/#controller" xmlns:gazebo="http://playerstage.sourceforge.net/gazebo/xmlschema/#gz" xmlns:geom="http://playerstage.sourceforge.net/gazebo/xmlschema/#geom" xmlns:interface="http://playerstage.sourceforge.net/gazebo/xmlschema/#interface" xmlns:joint="http://playerstage.sourceforge.net/gazebo/xmlschema/#joint" xmlns:model="http://playerstage.sourceforge.net/gazebo/xmlschema/#model" xmlns:physics="http://playerstage.sourceforge.net/gazebo/xmlschema/#physics" xmlns:renderable="http://playerstage.sourceforge.net/gazebo/xmlschema/#renderable" xmlns:rendering="http://playerstage.sourceforge.net/gazebo/xmlschema/#rendering" xmlns:sensor="http://playerstage.sourceforge.net/gazebo/xmlschema/#sensor" xmlns:xacro="http://ros.org/wiki/xacro" xmlns:xi="http://www.w3.org/2001/XInclude">
  <link name="base_link">
    <visual>
      <origin rpy="0 0 0" xyz="0 0 0"/>
      <geometry>
        <mesh filename="package://carl_description/meshes/Base.dae"/>
      </geometry>
    </visual>
  </link>
  <link name="LeftWheel_link">
    <visual>
      <origin rpy="0 0 0" xyz="0 0 0"/>
      <geometry>
        <mesh filename="package://carl_description/meshes/Wheel.dae"/>
      </geometry>
    </visual>
    <collision>
      <origin rpy="0 0 0" xyz="0 0 .025"/>
      <geometry>
        <cylinder length="0.1" radius="0.25"/>
      </geometry>
    </collision>
  </link>
  <link name="RightWheel_link">
    <visual>
      <origin rpy="0 0 0" xyz="0 0 0"/>
      <geometry>
        <mesh filename="package://carl_description/meshes/Wheel.dae"/>
      </geometry>
    </visual>
    <collision>
      <origin rpy="0 0 0" xyz="0 0 .025"/>
      <geometry>
        <cylinder length="0.1" radius="0.25"/>
      </geometry>
    </collision>
  </link>
  <link name="CasterPlate_link">
    <visual>
      <origin rpy="0 0 1.5708" xyz="0 0 0"/>
      <geometry>
        <mesh filename="package://carl_description/meshes/casterPlate.dae"/>
      </geometry>
    </visual>
  </link>
  <link name="Caster_link">
    <visual>
      <origin rpy="0 0 1.5708" xyz="0 0 0"/>
      <geometry>
        <mesh filename="package://carl_description/meshes/caster.dae"/>
      </geometry>
    </visual>
    <collision>
      <origin rpy="0 0 0" xyz="0 0 -0.09"/>
      <geometry>
        <cylinder length="0.213" radius="0.116"/>
      </geometry>
    </collision>
  </link>
  <link name="RearLeftStrut_link">
    <visual>
      <origin rpy="0 0 -1.5708" xyz="0 0 0"/>
      <geometry>
        <mesh filename="package://carl_description/meshes/RearStrut.dae"/>
      </geometry>
    </visual>
    <collision>
      <origin rpy="0 0 0" xyz="0 -0.4 0.5275"/>
      <geometry>
        <box size="0.027 0.054 1.055"/>
      </geometry>
    </collision>
  </link>
  <link name="RearRightStrut_link">
    <visual>
      <origin rpy="0 0 -1.5708" xyz="0 0 0"/>
      <geometry>
        <mesh filename="package://carl_description/meshes/RearStrut.dae"/>
      </geometry>
    </visual>
    <collision>
      <origin rpy="0 0 0" xyz="0 0.4 0.5275"/>
      <geometry>
        <box size="0.027 0.054 1.055"/>
      </geometry>
    </collision>
  </link>
  <link name="TopPlate_link">
    <visual>
      <origin rpy="0 0 -1.5708" xyz="0 0 0"/>
      <geometry>
        <mesh filename="package://carl_description/meshes/TablePlate.dae"/>
      </geometry>
    </visual>
    <collision>
      <origin rpy="0 0 0" xyz="-.29 0 -0.299"/>
      <geometry>
        <box size="0.495 0.59 0.65"/>
      </geometry>
    </collision>
  </link>
  <link name="CameraLift_link">
    <visual>
      <origin rpy="0 0 1.5708" xyz="0 0 0"/>
      <geometry>
        <mesh filename="package://carl_description/meshes/CameraLift.dae"/>
      </geometry>
    </visual>
    <collision>
      <origin rpy="0 0 1.5708" xyz="0 0 0"/>
      <geometry>
        <mesh filename="package://carl_description/meshes/CameraLift.dae"/>
      </geometry>
    </collision>
  </link>
  <link name="CameraTiltBracket_link">
    <!--exists to move center of rotation for camera mount-->
  </link>
  <link name="CameraTiltPlate_link">
    <visual>
      <origin rpy="0 1.5708 0" xyz="0 0 0"/>
      <geometry>
        <mesh filename="package://carl_description/meshes/CameraPlate.dae"/>
      </geometry>
    </visual>
    <collision>
      <origin rpy="0 1.5708 0" xyz="0 0 0"/>
      <geometry>
        <mesh filename="package://carl_description/meshes/CameraPlate.dae"/>
      </geometry>
    </collision>
  </link>
  <link name="JacoMount_link">
    <visual>
      <origin rpy="0 0 1.5708" xyz="0 0 0"/>
      <geometry>
        <mesh filename="package://carl_description/meshes/JacoMount.dae"/>
      </geometry>
    </visual>
  </link>
  <link name="Hokuyo_link">
    <visual>
      <origin rpy="0 0 0" xyz="0 0 0"/>
      <geometry>
        <mesh filename="package://carl_description/meshes/Hokuyo.dae"/>
      </geometry>
    </visual>
  </link>
  <link name="LeftSideWall_link">
    <visual>
      <origin rpy="0 0 1.5708" xyz="0 0 0"/>
      <geometry>
        <mesh filename="package://carl_description/meshes/SideWall.dae"/>
      </geometry>
    </visual>
  </link>
  <link name="RightSideWall_link">
    <visual>
      <origin rpy="0 0 1.5708" xyz="0 0 0"/>
      <geometry>
        <mesh filename="package://carl_description/meshes/SideWall.dae"/>
      </geometry>
    </visual>
  </link>
  <link name="FrontCover_link">
    <visual>
      <origin rpy="0 0 1.5708" xyz="0 0 0"/>
      <geometry>
        <mesh filename="package://carl_description/meshes/FrontCover.dae"/>
      </geometry>
    </visual>
    <collision>
      <origin rpy="0 0 0" xyz="-.245 0 -.241"/>
      <geometry>
        <mesh filename="package://carl_description/meshes/FrontCoverCollision.STL"/>
      </geometry>
    </collision>
  </link>
  <link name="BackCover_link">
    <visual>
      <origin rpy="0 0 0" xyz="0 0 0"/>
      <geometry>
        <!--<box size="0.005 0.45 0.6" />-->
        <mesh filename="package://carl_description/meshes/BackCover.dae"/>
      </geometry>
    </visual>
  </link>
  <joint name="BaseToLeftWheel" type="continuous">
    <parent link="base_link"/>
    <child link="LeftWheel_link"/>
    <origin rpy="-1.5708 0 0" xyz="0 0.25 0"/>
    <axis xyz="0 0 1"/>
  </joint>
  <joint name="BaseToRightWheel" type="continuous">
    <parent link="base_link"/>
    <child link="RightWheel_link"/>
    <origin rpy="1.5708 0 0" xyz="0 -0.25 0"/>
    <axis xyz="0 0 1"/>
  </joint>
  <joint name="BaseToCasterPlate" type="fixed">
    <parent link="base_link"/>
    <child link="CasterPlate_link"/>
    <origin rpy="0 0 0" xyz="0.2883 0 0"/>
  </joint>
  <joint name="CasterPlateToCaster" type="continuous">
    <parent link="CasterPlate_link"/>
    <child link="Caster_link"/>
    <origin rpy="0 0 0" xyz="0.0267 0 -0.024"/>
    <axis xyz="0 0 1"/>
  </joint>
  <joint name="BaseToRearLeftStrut" type="fixed">
    <parent link="base_link"/>
    <child link="RearLeftStrut_link"/>
    <origin rpy="0 0 0" xyz="-0.222 0.200 -0.102"/>
  </joint>
  <joint name="BaseToRearRightStrut" type="fixed">
    <parent link="base_link"/>
    <child link="RearRightStrut_link"/>
    <origin rpy="0 0 0" xyz="-0.222 -0.200 -0.102"/>
  </joint>
  <joint name="RearLeftStrutToTopPlate" type="fixed">
    <parent link="RearRightStrut_link"/>
    <child link="TopPlate_link"/>
    <origin rpy="0 0 0" xyz="0.516 0.20 0.598"/>
  </joint>
  <joint name="RearLeftStrutToCameraLift" type="fixed">
    <parent link="RearRightStrut_link"/>
    <child link="CameraLift_link"/>
    <origin rpy="0 0 0" xyz="0.01 0.20 1.461"/>
  </joint>
  <joint name="CameraLiftToCameraTiltBracket" type="continuous">
    <parent link="CameraLift_link"/>
    <child link="CameraTiltBracket_link"/>
    <origin rpy="1.5708 0 0" xyz="0.03 -0.10 0"/>
    <axis xyz="0 0 1"/>
  </joint>
  <joint name="CameraLiftBracketToCameraTiltPlate" type="fixed">
    <parent link="CameraTiltBracket_link"/>
    <child link="CameraTiltPlate_link"/>
    <origin rpy="0 0 0" xyz="0.11 0 -0.10"/>
  </joint>
  <joint name="TopPlateToJacoMount" type="fixed">
    <parent link="TopPlate_link"/>
    <child link="JacoMount_link"/>
    <origin rpy="0 0 0" xyz="0 0 -0.13"/>
  </joint>
  <joint name="CasterToHokuyo" type="fixed">
    <parent link="CasterPlate_link"/>
    <child link="Hokuyo_link"/>
    <origin rpy="0 0 0" xyz="0.07 0 0.035"/>
  </joint>
  <joint name="RearLeftStrutToLeftSideWall" type="fixed">
    <parent link="RearLeftStrut_link"/>
    <child link="LeftSideWall_link"/>
    <origin rpy="0 0 0" xyz="0.229 0.026 0.447"/>
  </joint>
  <joint name="RearRightStrutToRightSideWall" type="fixed">
    <parent link="RearRightStrut_link"/>
    <child link="RightSideWall_link"/>
    <origin rpy="0 0 0" xyz="0.229 -0.026 0.447"/>
  </joint>
  <joint name="BaseToFrontCover" type="fixed">
    <parent link="base_link"/>
    <child link="FrontCover_link"/>
    <origin rpy="0 0 0" xyz=".247 0 0.242"/>
  </joint>
  <joint name="BaseToBackCover" type="fixed">
    <parent link="base_link"/>
    <child link="BackCover_link"/>
    <origin rpy="0 0 0" xyz="-.237 0 -0.102"/>
  </joint>
  <link name="jaco_link_base">
    <visual>
      <geometry>
        <mesh filename="package://jaco_model/meshes/jaco_link_base.dae"/>
      </geometry>
      <material name="carbon_fiber">
        <color rgba="0.792156862745098 0.819607843137255 0.933333333333333 1"/>
      </material>
    </visual>
    <collision>
      <geometry>
        <mesh filename="package://jaco_model/meshes/jaco_link_base.dae"/>
      </geometry>
    </collision>
  </link>
  <joint name="jaco_joint_base" type="fixed">
    <parent link="JacoMount_link"/>
    <child link="jaco_link_base"/>
    <axis xyz="0 0 0"/>
    <origin rpy="0 0 0" xyz="0 0 0"/>
  </joint>
  <link name="jaco_link_1">
    <visual>
      <geometry>
        <mesh filename="package://jaco_model/meshes/jaco_link_1.dae"/>
      </geometry>
      <material name="carbon_fiber">
        <color rgba="0.792156862745098 0.819607843137255 0.933333333333333 1"/>
      </material>
    </visual>
    <collision>
      <geometry>
        <mesh filename="package://jaco_model/meshes/jaco_link_1.dae"/>
      </geometry>
    </collision>
  </link>
  <joint name="jaco_joint_1" type="continuous">
    <parent link="jaco_link_base"/>
    <child link="jaco_link_1"/>
    <axis xyz="0 0 1"/>
    <origin rpy="3.14159265359 0 0" xyz="0 0 0.1535"/>
  </joint>
  <link name="jaco_link_2">
    <visual>
      <geometry>
        <mesh filename="package://jaco_model/meshes/jaco_link_2.dae"/>
      </geometry>
      <material name="carbon_fiber">
        <color rgba="0.792156862745098 0.819607843137255 0.933333333333333 1"/>
      </material>
    </visual>
    <collision>
      <geometry>
        <mesh filename="package://jaco_model/meshes/jaco_link_2.dae"/>
      </geometry>
    </collision>
  </link>
  <joint name="jaco_joint_2" type="continuous">
    <parent link="jaco_link_1"/>
    <child link="jaco_link_2"/>
    <axis xyz="0 0 1"/>
    <origin rpy="-1.57079632679 -1.57079632679 0" xyz="0 0 -0.1185"/>
  </joint>
  <link name="jaco_link_3">
    <visual>
      <geometry>
        <mesh filename="package://jaco_model/meshes/jaco_link_3.dae"/>
      </geometry>
      <material name="carbon_fiber">
        <color rgba="0.792156862745098 0.819607843137255 0.933333333333333 1"/>
      </material>
    </visual>
    <collision>
      <geometry>
        <mesh filename="package://jaco_model/meshes/jaco_link_3.dae"/>
      </geometry>
    </collision>
  </link>
  <joint name="jaco_joint_3" type="continuous">
    <parent link="jaco_link_2"/>
    <child link="jaco_link_3"/>
    <axis xyz="0 0 1"/>
    <origin rpy="3.14159265359 0 3.14159265359" xyz="0.41 0 0"/>
  </joint>
  <link name="jaco_link_4">
    <visual>
      <geometry>
        <mesh filename="package://jaco_model/meshes/jaco_link_4.dae"/>
      </geometry>
      <material name="carbon_fiber">
        <color rgba="0.792156862745098 0.819607843137255 0.933333333333333 1"/>
      </material>
    </visual>
    <collision>
      <geometry>
        <mesh filename="package://jaco_model/meshes/jaco_link_4.dae"/>
      </geometry>
    </collision>
  </link>
  <joint name="jaco_joint_4" type="continuous">
    <parent link="jaco_link_3"/>
    <child link="jaco_link_4"/>
    <axis xyz="0 0 1"/>
    <origin rpy="0 -1.57079632679 0" xyz="0.207 0 -0.01125"/>
  </joint>
  <link name="jaco_link_5">
    <visual>
      <geometry>
        <mesh filename="package://jaco_model/meshes/jaco_link_5.dae"/>
      </geometry>
      <material name="carbon_fiber">
        <color rgba="0.792156862745098 0.819607843137255 0.933333333333333 1"/>
      </material>
    </visual>
    <collision>
      <geometry>
        <mesh filename="package://jaco_model/meshes/jaco_link_5.dae"/>
      </geometry>
    </collision>
  </link>
  <joint name="jaco_joint_5" type="continuous">
    <parent link="jaco_link_4"/>
    <child link="jaco_link_5"/>
    <axis xyz="0 0 1"/>
    <origin rpy="0 0.959931088597 3.14159265359" xyz="0.0343 0 -0.06588"/>
  </joint>
  <link name="jaco_link_hand">
    <visual>
      <geometry>
        <mesh filename="package://jaco_model/meshes/jaco_link_hand.dae"/>
      </geometry>
      <material name="carbon_fiber">
        <color rgba="0.792156862745098 0.819607843137255 0.933333333333333 1"/>
      </material>
    </visual>
    <collision>
      <geometry>
        <mesh filename="package://jaco_model/meshes/jaco_link_hand.dae"/>
      </geometry>
    </collision>
  </link>
  <joint name="jaco_joint_6" type="continuous">
    <parent link="jaco_link_5"/>
    <child link="jaco_link_hand"/>
    <axis xyz="0 0 1"/>
    <origin rpy="0 0.959931088597 3.14159265359" xyz="0.0343 0 -0.06588"/>
  </joint>
  <link name="jaco_link_finger_1">
    <visual>
      <geometry>
        <mesh filename="package://jaco_model/meshes/jaco_link_finger_1.dae"/>
      </geometry>
      <material name="carbon_fiber">
        <color rgba="0.792156862745098 0.819607843137255 0.933333333333333 1"/>
      </material>
    </visual>
    <collision>
      <geometry>
        <mesh filename="package://jaco_model/meshes/jaco_link_finger_1.dae"/>
      </geometry>
    </collision>
  </link>
  <joint name="jaco_joint_finger_1" type="revolute">
    <parent link="jaco_link_hand"/>
    <child link="jaco_link_finger_1"/>
    <axis xyz="0 0 1"/>
    <origin rpy="-1.7983 1.117 3.1416" xyz="-0.03978 0 -0.10071"/>
    <limit effort="30" lower="0" upper="0.698131700798" velocity="5"/>
  </joint>
  <link name="jaco_link_finger_2">
    <visual>
      <geometry>
        <mesh filename="package://jaco_model/meshes/jaco_link_finger_2.dae"/>
      </geometry>
      <material name="carbon_fiber">
        <color rgba="0.792156862745098 0.819607843137255 0.933333333333333 1"/>
      </material>
    </visual>
    <collision>
      <geometry>
        <mesh filename="package://jaco_model/meshes/jaco_link_finger_2.dae"/>
      </geometry>
    </collision>
  </link>
  <joint name="jaco_joint_finger_2" type="revolute">
    <parent link="jaco_link_hand"/>
    <child link="jaco_link_finger_2"/>
    <axis xyz="0 0 1"/>
    <origin rpy="-1.6222 1.117 -0.23615" xyz="0.03569 -0.0216 -0.10071"/>
    <limit effort="30" lower="0" upper="0.698131700798" velocity="5"/>
  </joint>
  <link name="jaco_link_finger_3">
    <visual>
      <geometry>
        <mesh filename="package://jaco_model/meshes/jaco_link_finger_3.dae"/>
      </geometry>
      <material name="carbon_fiber">
        <color rgba="0.792156862745098 0.819607843137255 0.933333333333333 1"/>
      </material>
    </visual>
    <collision>
      <geometry>
        <mesh filename="package://jaco_model/meshes/jaco_link_finger_3.dae"/>
      </geometry>
    </collision>
  </link>
  <joint name="jaco_joint_finger_3" type="revolute">
    <parent link="jaco_link_hand"/>
    <child link="jaco_link_finger_3"/>
    <axis xyz="0 0 1"/>
    <origin rpy="-1.5161 1.1459 0.23978" xyz="0.03569 0.0216 -0.10071"/>
    <limit effort="30" lower="0" upper="0.698131700798" velocity="5"/>
  </joint>
</robot>

