<?xml version="1.0" ?>
<!-- =================================================================================== -->
<!-- |    This document was autogenerated by xacro from carl.xacro                     | -->
<!-- |    EDITING THIS FILE BY HAND IS NOT RECOMMENDED                                 | -->
<!-- =================================================================================== -->
<robot name="carl" xmlns:body="http://playerstage.sourceforge.net/gazebo/xmlschema/#body" xmlns:controller="http://playerstage.sourceforge.net/gazebo/xmlschema/#controller" xmlns:gazebo="http://playerstage.sourceforge.net/gazebo/xmlschema/#gz" xmlns:geom="http://playerstage.sourceforge.net/gazebo/xmlschema/#geom" xmlns:interface="http://playerstage.sourceforge.net/gazebo/xmlschema/#interface" xmlns:joint="http://playerstage.sourceforge.net/gazebo/xmlschema/#joint" xmlns:model="http://playerstage.sourceforge.net/gazebo/xmlschema/#model" xmlns:physics="http://playerstage.sourceforge.net/gazebo/xmlschema/#physics" xmlns:renderable="http://playerstage.sourceforge.net/gazebo/xmlschema/#renderable" xmlns:rendering="http://playerstage.sourceforge.net/gazebo/xmlschema/#rendering" xmlns:sensor="http://playerstage.sourceforge.net/gazebo/xmlschema/#sensor" xmlns:xacro="http://ros.org/wiki/xacro" xmlns:xi="http://www.w3.org/2001/XInclude">
  <link name="base_link">
    <visual>
      <origin rpy="0 0 0" xyz="0 0 0"/>
      <geometry>
        <mesh filename="package://carl_description/meshes/FullRobot_-_RMP_210-1_RMP_Powerbase-1.STL"/>
      </geometry>
    </visual>
  </link>
  <link name="LeftWheel_link">
    <visual>
      <origin rpy="1.5708 0 0" xyz="0 0.02 -0.32"/>
      <geometry>
        <mesh filename="package://carl_description/meshes/FullRobot_-_RMP_210-1_StandardWheel-2.STL"/>
      </geometry>
    </visual>
    <collision>
      <origin rpy="0 0 0" xyz="0 0 -0.045"/>
      <geometry>
        <cylinder length="0.090" radius="0.25"/>
      </geometry>
    </collision>
  </link>
  <link name="RightWheel_link">
    <visual>
      <origin rpy="-1.5708 0 0" xyz="0 -0.02 -0.32"/>
      <geometry>
        <mesh filename="package://carl_description/meshes/FullRobot_-_RMP_210-1_StandardWheel-1.STL"/>
      </geometry>
    </visual>
    <collision>
      <origin rpy="0 0 0" xyz="0 0 -0.045"/>
      <geometry>
        <cylinder length="0.090" radius="0.25"/>
      </geometry>
    </collision>
  </link>
  <link name="Caster_link">
    <visual>
      <origin rpy="0 0 0" xyz="0 0 0"/>
      <geometry>
        <mesh filename="package://carl_description/meshes/FullRobot_-_RMP_210-1_CasterAssembly-1.STL"/>
      </geometry>
    </visual>
  </link>
  <link name="RearLeftStrut_link">
    <visual>
      <origin rpy="0 0 0" xyz="0.222 -0.20 -0.194"/>
      <geometry>
        <mesh filename="package://carl_description/meshes/FullRobot_-_SuperStructure-1_RearVerticalStrut-1.STL"/>
      </geometry>
    </visual>
    <collision>
      <origin rpy="0 0 0" xyz="0 -0.40 0.24"/>
      <geometry>
        <box size="0.025 0.051 1.055"/>
      </geometry>
    </collision>
  </link>
  <link name="RearRightStrut_link">
    <visual>
      <origin rpy="0 0 0" xyz="0.222 0.20 -0.194"/>
      <geometry>
        <mesh filename="package://carl_description/meshes/FullRobot_-_SuperStructure-1_RearVerticalStrut-2.STL"/>
      </geometry>
    </visual>
    <collision>
      <origin rpy="0 0 0" xyz="0 0.40 0.24"/>
      <geometry>
        <box size="0.025 0.051 1.055"/>
      </geometry>
    </collision>
  </link>
  <link name="TopPlate_link">
    <visual>
      <origin rpy="0 0 0" xyz="-.08 0 -0.495"/>
      <geometry>
        <mesh filename="package://carl_description/meshes/FullRobot_-_SuperStructure-1_Table_Plate-1.STL"/>
      </geometry>
    </visual>
    <collision>
      <!--<origin xyz="-.055 0 -0.295" rpy="0 0 0" />-->
      <origin rpy="0 0 0" xyz="-.068 0 -0.295"/>
      <geometry>
        <!--<box size="0.465 0.584 0.6" />-->
        <box size="0.483 0.584 0.6"/>
      </geometry>
    </collision>
  </link>
  <link name="CameraLift_link">
    <visual>
      <origin rpy="0 0 0" xyz="0.22 0 -1.36"/>
      <geometry>
        <mesh filename="package://carl_description/meshes/FullRobot_-_tempHorizontal-1.STL"/>
      </geometry>
    </visual>
  </link>
  <link name="CameraTiltBracket_link">
    <!--exists to move center of rotation for camera mount-->
  </link>
  <link name="CameraTiltPlate_link">
    <visual>
      <origin rpy="-1.5708 0 -2.1" xyz="-1.24 .54 0 "/>
      <geometry>
        <mesh filename="package://carl_description/meshes/FullRobot_-_tempPlate-1.STL"/>
      </geometry>
    </visual>
  </link>
  <link name="JacoMount_link">
    <visual>
      <origin rpy="0 0 0" xyz="-0.295 0 -0.367"/>
      <geometry>
        <mesh filename="package://carl_description/meshes/FullRobot_-_SuperStructure-1_ArmMountHoriz-1.STL"/>
      </geometry>
    </visual>
  </link>
  <link name="Hokuyo_link">
    <visual>
      <origin rpy="0 0 0" xyz="-0.36 0 0"/>
      <geometry>
        <mesh filename="package://carl_description/meshes/FullRobot_-_hokuyo-1.STL"/>
      </geometry>
    </visual>
  </link>
  <link name="LeftSideWall_link">
    <visual>
      <origin rpy="0 0 0" xyz="0 -.225 -.27"/>
      <geometry>
        <mesh filename="package://carl_description/meshes/FullRobot_-_sideWall-1.STL"/>
      </geometry>
    </visual>
  </link>
  <link name="RightSideWall_link">
    <visual>
      <origin rpy="0 0 0" xyz="0 -.225 -.27"/>
      <geometry>
        <mesh filename="package://carl_description/meshes/FullRobot_-_sideWall-1.STL"/>
      </geometry>
    </visual>
  </link>
  <link name="FrontCover_link">
    <visual>
      <origin rpy="0 0 0" xyz="0 0 -.012"/>
      <geometry>
        <mesh filename="package://carl_description/meshes/FullRobot_-_FrontCover-1.STL"/>
      </geometry>
    </visual>
    <collision>
      <origin rpy="0 0 0" xyz="0 0 -.012"/>
      <geometry>
        <mesh filename="package://carl_description/meshes/FrontCoverCollision.STL"/>
      </geometry>
    </collision>
  </link>
  <joint name="BaseToLeftWheel" type="continuous">
    <parent link="base_link"/>
    <child link="LeftWheel_link"/>
    <origin rpy="-1.5708 0 0" xyz="0.02 0.32 0"/>
    <axis xyz="0 0 1"/>
  </joint>
  <joint name="BaseToRightWheel" type="continuous">
    <parent link="base_link"/>
    <child link="RightWheel_link"/>
    <origin rpy="1.5708 0 0" xyz="0.02 -0.32 0"/>
    <axis xyz="0 0 1"/>
  </joint>
  <joint name="BaseToCaster" type="fixed">
    <parent link="base_link"/>
    <child link="Caster_link"/>
    <origin rpy="0 0 0" xyz="0 0 0"/>
  </joint>
  <joint name="BaseToRearLeftStrut" type="fixed">
    <parent link="base_link"/>
    <child link="RearLeftStrut_link"/>
    <origin rpy="0 0 0" xyz="-0.222 0.20 0.194"/>
  </joint>
  <joint name="BaseToRearRightStrut" type="fixed">
    <parent link="base_link"/>
    <child link="RearRightStrut_link"/>
    <origin rpy="0 0 0" xyz="-0.222 -0.20 0.194"/>
  </joint>
  <joint name="RearLeftStrutToTopPlate" type="fixed">
    <parent link="RearRightStrut_link"/>
    <child link="TopPlate_link"/>
    <origin rpy="0 0 0" xyz="0.30 0.20 0.30"/>
  </joint>
  <joint name="RearLeftStrutToCameraLift" type="fixed">
    <parent link="RearRightStrut_link"/>
    <child link="CameraLift_link"/>
    <origin rpy="0 0 0" xyz="0.01 0.20 1.17"/>
  </joint>
  <joint name="CameraLiftToCameraTiltBracket" type="continuous">
    <parent link="CameraLift_link"/>
    <child link="CameraTiltBracket_link"/>
    <origin rpy="1.5708 0 0" xyz="0.03 -0.10 0"/>
    <axis xyz="0 0 1"/>
  </joint>
  <joint name="CameraLiftBracketToCameraTiltPlate" type="fixed">
    <parent link="CameraTiltBracket_link"/>
    <child link="CameraTiltPlate_link"/>
    <origin rpy="0 0 0" xyz="0.11 0 -0.10"/>
  </joint>
  <joint name="TopPlateToJacoMount" type="fixed">
    <parent link="TopPlate_link"/>
    <child link="JacoMount_link"/>
    <origin rpy="0 0 0" xyz="0.216 0 -0.13"/>
  </joint>
  <joint name="CasterToHokuyo" type="fixed">
    <parent link="Caster_link"/>
    <child link="Hokuyo_link"/>
    <origin rpy="0 0 0" xyz="0.36 0 0"/>
  </joint>
  <joint name="RearLeftStrutToLeftSideWall" type="fixed">
    <parent link="RearLeftStrut_link"/>
    <child link="LeftSideWall_link"/>
    <origin rpy="0 0 0" xyz="0.229 0.025 0.078"/>
  </joint>
  <joint name="RearRightStrutToRightSideWall" type="fixed">
    <parent link="RearRightStrut_link"/>
    <child link="RightSideWall_link"/>
    <origin rpy="0 0 0" xyz="0.229 -0.025 0.078"/>
  </joint>
  <joint name="BaseToFrontCover" type="fixed">
    <parent link="base_link"/>
    <child link="FrontCover_link"/>
    <origin rpy="0 0 0" xyz="0 0 0.012"/>
  </joint>
  <link name="jaco_link_base">
    <visual>
      <geometry>
        <mesh filename="package://jaco_model/meshes/jaco_link_base.dae"/>
      </geometry>
      <material name="carbon_fiber">
        <color rgba="0.792156862745098 0.819607843137255 0.933333333333333 1"/>
      </material>
    </visual>
    <collision>
      <geometry>
        <mesh filename="package://jaco_model/meshes/jaco_link_base.dae"/>
      </geometry>
    </collision>
  </link>
  <joint name="jaco_joint_base" type="fixed">
    <parent link="JacoMount_link"/>
    <child link="jaco_link_base"/>
    <axis xyz="0 0 0"/>
    <origin rpy="0 0 0" xyz="0 0 0"/>
  </joint>
  <link name="jaco_link_1">
    <visual>
      <geometry>
        <mesh filename="package://jaco_model/meshes/jaco_link_1.dae"/>
      </geometry>
      <material name="carbon_fiber">
        <color rgba="0.792156862745098 0.819607843137255 0.933333333333333 1"/>
      </material>
    </visual>
    <collision>
      <geometry>
        <mesh filename="package://jaco_model/meshes/jaco_link_1.dae"/>
      </geometry>
    </collision>
  </link>
  <joint name="jaco_joint_1" type="continuous">
    <parent link="jaco_link_base"/>
    <child link="jaco_link_1"/>
    <axis xyz="0 0 1"/>
    <origin rpy="3.14159265359 0 0" xyz="0 0 0.1535"/>
  </joint>
  <link name="jaco_link_2">
    <visual>
      <geometry>
        <mesh filename="package://jaco_model/meshes/jaco_link_2.dae"/>
      </geometry>
      <material name="carbon_fiber">
        <color rgba="0.792156862745098 0.819607843137255 0.933333333333333 1"/>
      </material>
    </visual>
    <collision>
      <geometry>
        <mesh filename="package://jaco_model/meshes/jaco_link_2.dae"/>
      </geometry>
    </collision>
  </link>
  <joint name="jaco_joint_2" type="continuous">
    <parent link="jaco_link_1"/>
    <child link="jaco_link_2"/>
    <axis xyz="0 0 1"/>
    <origin rpy="-1.57079632679 -1.57079632679 0" xyz="0 0 -0.1185"/>
  </joint>
  <link name="jaco_link_3">
    <visual>
      <geometry>
        <mesh filename="package://jaco_model/meshes/jaco_link_3.dae"/>
      </geometry>
      <material name="carbon_fiber">
        <color rgba="0.792156862745098 0.819607843137255 0.933333333333333 1"/>
      </material>
    </visual>
    <collision>
      <geometry>
        <mesh filename="package://jaco_model/meshes/jaco_link_3.dae"/>
      </geometry>
    </collision>
  </link>
  <joint name="jaco_joint_3" type="continuous">
    <parent link="jaco_link_2"/>
    <child link="jaco_link_3"/>
    <axis xyz="0 0 1"/>
    <origin rpy="3.14159265359 0 3.14159265359" xyz="0.41 0 0"/>
  </joint>
  <link name="jaco_link_4">
    <visual>
      <geometry>
        <mesh filename="package://jaco_model/meshes/jaco_link_4.dae"/>
      </geometry>
      <material name="carbon_fiber">
        <color rgba="0.792156862745098 0.819607843137255 0.933333333333333 1"/>
      </material>
    </visual>
    <collision>
      <geometry>
        <mesh filename="package://jaco_model/meshes/jaco_link_4.dae"/>
      </geometry>
    </collision>
  </link>
  <joint name="jaco_joint_4" type="continuous">
    <parent link="jaco_link_3"/>
    <child link="jaco_link_4"/>
    <axis xyz="0 0 1"/>
    <origin rpy="0 -1.57079632679 0" xyz="0.207 0 -0.01125"/>
  </joint>
  <link name="jaco_link_5">
    <visual>
      <geometry>
        <mesh filename="package://jaco_model/meshes/jaco_link_5.dae"/>
      </geometry>
      <material name="carbon_fiber">
        <color rgba="0.792156862745098 0.819607843137255 0.933333333333333 1"/>
      </material>
    </visual>
    <collision>
      <geometry>
        <mesh filename="package://jaco_model/meshes/jaco_link_5.dae"/>
      </geometry>
    </collision>
  </link>
  <joint name="jaco_joint_5" type="continuous">
    <parent link="jaco_link_4"/>
    <child link="jaco_link_5"/>
    <axis xyz="0 0 1"/>
    <origin rpy="0 0.959931088597 3.14159265359" xyz="0.0343 0 -0.06588"/>
  </joint>
  <link name="jaco_link_hand">
    <visual>
      <geometry>
        <mesh filename="package://jaco_model/meshes/jaco_link_hand.dae"/>
      </geometry>
      <material name="carbon_fiber">
        <color rgba="0.792156862745098 0.819607843137255 0.933333333333333 1"/>
      </material>
    </visual>
    <collision>
      <geometry>
        <mesh filename="package://jaco_model/meshes/jaco_link_hand.dae"/>
      </geometry>
    </collision>
  </link>
  <joint name="jaco_joint_6" type="continuous">
    <parent link="jaco_link_5"/>
    <child link="jaco_link_hand"/>
    <axis xyz="0 0 1"/>
    <origin rpy="0 0.959931088597 3.14159265359" xyz="0.0343 0 -0.06588"/>
  </joint>
  <link name="jaco_link_finger_1">
    <visual>
      <geometry>
        <mesh filename="package://jaco_model/meshes/jaco_link_finger_1.dae"/>
      </geometry>
      <material name="carbon_fiber">
        <color rgba="0.792156862745098 0.819607843137255 0.933333333333333 1"/>
      </material>
    </visual>
    <collision>
      <geometry>
        <mesh filename="package://jaco_model/meshes/jaco_link_finger_1.dae"/>
      </geometry>
    </collision>
  </link>
  <joint name="jaco_joint_finger_1" type="revolute">
    <parent link="jaco_link_hand"/>
    <child link="jaco_link_finger_1"/>
    <axis xyz="0 0 1"/>
    <origin rpy="-1.7983 1.117 3.1416" xyz="-0.03978 0 -0.10071"/>
    <limit effort="30" lower="0" upper="0.698131700798" velocity="5"/>
  </joint>
  <link name="jaco_link_finger_2">
    <visual>
      <geometry>
        <mesh filename="package://jaco_model/meshes/jaco_link_finger_2.dae"/>
      </geometry>
      <material name="carbon_fiber">
        <color rgba="0.792156862745098 0.819607843137255 0.933333333333333 1"/>
      </material>
    </visual>
    <collision>
      <geometry>
        <mesh filename="package://jaco_model/meshes/jaco_link_finger_2.dae"/>
      </geometry>
    </collision>
  </link>
  <joint name="jaco_joint_finger_2" type="revolute">
    <parent link="jaco_link_hand"/>
    <child link="jaco_link_finger_2"/>
    <axis xyz="0 0 1"/>
    <origin rpy="-1.6222 1.117 -0.23615" xyz="0.03569 -0.0216 -0.10071"/>
    <limit effort="30" lower="0" upper="0.698131700798" velocity="5"/>
  </joint>
  <link name="jaco_link_finger_3">
    <visual>
      <geometry>
        <mesh filename="package://jaco_model/meshes/jaco_link_finger_3.dae"/>
      </geometry>
      <material name="carbon_fiber">
        <color rgba="0.792156862745098 0.819607843137255 0.933333333333333 1"/>
      </material>
    </visual>
    <collision>
      <geometry>
        <mesh filename="package://jaco_model/meshes/jaco_link_finger_3.dae"/>
      </geometry>
    </collision>
  </link>
  <joint name="jaco_joint_finger_3" type="revolute">
    <parent link="jaco_link_hand"/>
    <child link="jaco_link_finger_3"/>
    <axis xyz="0 0 1"/>
    <origin rpy="-1.5161 1.1459 0.23978" xyz="0.03569 0.0216 -0.10071"/>
    <limit effort="30" lower="0" upper="0.698131700798" velocity="5"/>
  </joint>
</robot>

