<?xml version="1.0" ?>
<!-- =================================================================================== -->
<!-- |    This document was autogenerated by xacro from carl_description/robots/carl.urdf.xacro | -->
<!-- |    EDITING THIS FILE BY HAND IS NOT RECOMMENDED                                 | -->
<!-- =================================================================================== -->
<robot name="carl" xmlns:body="http://playerstage.sourceforge.net/gazebo/xmlschema/#body" xmlns:controller="http://playerstage.sourceforge.net/gazebo/xmlschema/#controller" xmlns:gazebo="http://playerstage.sourceforge.net/gazebo/xmlschema/#gz" xmlns:geom="http://playerstage.sourceforge.net/gazebo/xmlschema/#geom" xmlns:interface="http://playerstage.sourceforge.net/gazebo/xmlschema/#interface" xmlns:joint="http://playerstage.sourceforge.net/gazebo/xmlschema/#joint" xmlns:model="http://playerstage.sourceforge.net/gazebo/xmlschema/#model" xmlns:physics="http://playerstage.sourceforge.net/gazebo/xmlschema/#physics" xmlns:renderable="http://playerstage.sourceforge.net/gazebo/xmlschema/#renderable" xmlns:rendering="http://playerstage.sourceforge.net/gazebo/xmlschema/#rendering" xmlns:sensor="http://playerstage.sourceforge.net/gazebo/xmlschema/#sensor" xmlns:xacro="http://ros.org/wiki/xacro" xmlns:xi="http://www.w3.org/2001/XInclude">
  <joint name="base_link_left_rear_strut_joint" type="fixed">
    <origin rpy="0 0 0" xyz="-0.222 0.200 -0.102"/>
    <parent link="base_link"/>
    <child link="left_rear_strut_link"/>
  </joint>
  <joint name="left_rear_strut_link_left_rear_strut_top_link_joint" type="fixed">
    <parent link="left_rear_strut_link"/>
    <child link="left_rear_strut_top_link"/>
    <origin rpy="0 0 0" xyz="0 0.001 1.055"/>
  </joint>
  <link name="left_rear_strut_link">
    <visual>
      <origin rpy="0 0 -1.5708" xyz="0 0 0"/>
      <geometry>
        <mesh filename="package://carl_description/meshes/rear_strut.min.dae"/>
      </geometry>
    </visual>
    <collision>
      <origin rpy="0 0 0" xyz="0 0 0.5275"/>
      <geometry>
        <box size="0.027 0.054 1.055"/>
      </geometry>
    </collision>
  </link>
  <link name="left_rear_strut_top_link">
    <visual>
      <origin rpy="0 0 -1.5708" xyz="0 0 0"/>
      <geometry>
        <mesh filename="package://carl_description/meshes/rear_strut_top.min.dae"/>
      </geometry>
    </visual>
    <collision>
      <origin rpy="0 0 0" xyz="0 -0.001 0.2285"/>
      <geometry>
        <box size="0.027 0.054 0.4575"/>
      </geometry>
    </collision>
  </link>
  <joint name="base_link_right_rear_strut_joint" type="fixed">
    <origin rpy="0 0 3.1415926536" xyz="-0.222 -0.200 -0.102"/>
    <parent link="base_link"/>
    <child link="right_rear_strut_link"/>
  </joint>
  <joint name="right_rear_strut_link_right_rear_strut_top_link_joint" type="fixed">
    <parent link="right_rear_strut_link"/>
    <child link="right_rear_strut_top_link"/>
    <origin rpy="0 0 0" xyz="0 0.001 1.055"/>
  </joint>
  <link name="right_rear_strut_link">
    <visual>
      <origin rpy="0 0 -1.5708" xyz="0 0 0"/>
      <geometry>
        <mesh filename="package://carl_description/meshes/rear_strut.min.dae"/>
      </geometry>
    </visual>
    <collision>
      <origin rpy="0 0 0" xyz="0 0 0.5275"/>
      <geometry>
        <box size="0.027 0.054 1.055"/>
      </geometry>
    </collision>
  </link>
  <link name="right_rear_strut_top_link">
    <visual>
      <origin rpy="0 0 -1.5708" xyz="0 0 0"/>
      <geometry>
        <mesh filename="package://carl_description/meshes/rear_strut_top.min.dae"/>
      </geometry>
    </visual>
    <collision>
      <origin rpy="0 0 0" xyz="0 -0.001 0.2285"/>
      <geometry>
        <box size="0.027 0.054 0.4575"/>
      </geometry>
    </collision>
  </link>
  <joint name="left_rear_strut_top_plate_joint" type="fixed">
    <parent link="right_rear_strut_link"/>
    <child link="top_plate_link"/>
    <origin rpy="0 0 3.14159265" xyz="-0.516 -0.20 0.598"/>
  </joint>
  <joint name="top_plate_jaco_mount" type="fixed">
    <parent link="top_plate_link"/>
    <child link="jaco_mount_link"/>
    <origin rpy="0 0 0" xyz="0 0 -0.13"/>
  </joint>
  <link name="top_plate_link">
    <visual>
      <origin rpy="0 0 -1.5708" xyz="0 0 0"/>
      <geometry>
        <mesh filename="package://carl_description/meshes/table_plate.min.dae"/>
      </geometry>
    </visual>
    <collision>
      <origin rpy="0 0 3.1415926536" xyz="-.29 0 -0.299"/>
      <geometry>
        <box size="0.495 0.59 0.65"/>
      </geometry>
    </collision>
  </link>
  <link name="jaco_mount_link">
    <visual>
      <origin rpy="0 0 1.5708" xyz="0 0 0"/>
      <geometry>
        <mesh filename="package://carl_description/meshes/jaco_mount.min.dae"/>
      </geometry>
    </visual>
  </link>
  <link name="asus_lift_link">
    <visual>
      <origin rpy="0 1.5708 1.5708" xyz="0 0 0"/>
      <geometry>
        <mesh filename="package://carl_description/meshes/camera_lift.min.dae"/>
      </geometry>
    </visual>
    <collision>
      <origin rpy="0 0 0" xyz="-0.0127 0 0"/>
      <geometry>
        <box size="0.027 0.454 0.054"/>
      </geometry>
    </collision>
  </link>
  <link name="asus_mount_link">
    <visual>
      <origin rpy="0 1.5708 0" xyz="0 0 0"/>
      <geometry>
        <mesh filename="package://carl_description/meshes/camera_mount.min.dae"/>
      </geometry>
    </visual>
  </link>
  <link name="asus_servo_mount_link">
    <visual>
      <origin rpy="0 0 0" xyz="0 0 0"/>
      <geometry>
        <mesh filename="package://carl_description/meshes/servo_mount.min.dae"/>
      </geometry>
    </visual>
    <collision>
      <origin rpy="0 0 0" xyz="0.023 0 0"/>
      <geometry>
        <box size="0.08 0.055 0.09"/>
      </geometry>
    </collision>
  </link>
  <link name="asus_servo_link">
    <visual>
      <origin rpy="0 0 0" xyz="0 0 0"/>
      <geometry>
        <mesh filename="package://carl_description/meshes/servo.min.dae"/>
      </geometry>
    </visual>
    <collision>
      <origin rpy="0 0 0" xyz="0.01 -0.021 0"/>
      <geometry>
        <box size="0.06 0.05 0.035"/>
      </geometry>
    </collision>
  </link>
  <link name="asus_servo_arm_link">
    <visual>
      <origin rpy="0 0 0" xyz="0 0 0"/>
      <geometry>
        <mesh filename="package://carl_description/meshes/servo_arm.min.dae"/>
      </geometry>
    </visual>
    <collision>
      <origin rpy="0 0 0" xyz="0 -0.01 -0.02"/>
      <geometry>
        <box size="0.035 0.05 0.06"/>
      </geometry>
    </collision>
  </link>
  <joint name="camera_joint" type="fixed">
    <origin rpy="0 -1.53 0" xyz="-0.016 -0.008 0.018"/>
    <parent link="asus_mount_link"/>
    <child link="camera_link"/>
  </joint>
  <link name="camera_link">
    <inertial>
      <mass value="0.01"/>
      <origin xyz="0 0 0"/>
      <inertia ixx="0.001" ixy="0.0" ixz="0.0" iyy="0.001" iyz="0.0" izz="0.001"/>
    </inertial>
    <visual>
      <origin rpy="-1.57079632679 -3.14159265359 -1.57079632679" xyz=" 0 0 0 "/>
      <geometry>
        <mesh filename="package://carl_description/meshes/asus_xtion_pro_live.min.dae" scale="0.001 0.001 0.001"/>
      </geometry>
    </visual>
    <collision>
      <origin rpy="0 0 0" xyz="0.0 0.0 0.0"/>
      <geometry>
        <box size="0.0730 .2760 0.0720"/>
      </geometry>
    </collision>
  </link>
  <joint name="camera_depth_joint" type="fixed">
    <origin rpy="0 0 0" xyz="0 0.049 0"/>
    <parent link="camera_link"/>
    <child link="camera_depth_frame"/>
  </joint>
  <link name="camera_depth_frame">
    <inertial>
      <mass value="0.01"/>
      <origin xyz="0 0 0"/>
      <inertia ixx="0.001" ixy="0.0" ixz="0.0" iyy="0.001" iyz="0.0" izz="0.001"/>
    </inertial>
  </link>
  <joint name="camera_depth_optical_joint" type="fixed">
    <origin rpy="-1.57079632679 0 -1.57079632679" xyz="0 0 0"/>
    <parent link="camera_depth_frame"/>
    <child link="camera_depth_optical_frame"/>
  </joint>
  <link name="camera_depth_optical_frame">
    <inertial>
      <mass value="0.001"/>
      <origin xyz="0 0 0"/>
      <inertia ixx="0.0001" ixy="0.0" ixz="0.0" iyy="0.0001" iyz="0.0" izz="0.0001"/>
    </inertial>
  </link>
  <joint name="camera_rgb_joint" type="fixed">
    <origin rpy="0 0 0" xyz="0 0.022 0"/>
    <parent link="camera_link"/>
    <child link="camera_rgb_frame"/>
  </joint>
  <link name="camera_rgb_frame">
    <inertial>
      <mass value="0.001"/>
      <origin xyz="0 0 0"/>
      <inertia ixx="0.0001" ixy="0.0" ixz="0.0" iyy="0.0001" iyz="0.0" izz="0.0001"/>
    </inertial>
  </link>
  <joint name="camera_rgb_optical_joint" type="fixed">
    <origin rpy="-1.57079632679 0 -1.57079632679" xyz="0 0 0"/>
    <parent link="camera_rgb_frame"/>
    <child link="camera_rgb_optical_frame"/>
  </joint>
  <link name="camera_rgb_optical_frame">
    <inertial>
      <mass value="0.001"/>
      <origin xyz="0 0 0"/>
      <inertia ixx="0.0001" ixy="0.0" ixz="0.0" iyy="0.0001" iyz="0.0" izz="0.0001"/>
    </inertial>
  </link>
  <joint name="right_rear_strut_asus_lift_joint" type="fixed">
    <parent link="right_rear_strut_link"/>
    <child link="asus_lift_link"/>
    <origin rpy="0 0 3.1415926536" xyz="-0.013 -0.20 1.538"/>
  </joint>
  <joint name="asus_lift_asus_servo_mount_joint" type="fixed">
    <parent link="asus_lift_link"/>
    <child link="asus_servo_mount_link"/>
    <origin rpy="1.5708 0 0" xyz="0 0 0"/>
    <axis xyz="0 0 1"/>
  </joint>
  <joint name="asus_servo_mount_asus_servo_joint" type="fixed">
    <parent link="asus_servo_mount_link"/>
    <child link="asus_servo_link"/>
    <origin rpy="1.5708 0 3.92699" xyz="0.073 0.013 0.0187"/>
  </joint>
  <joint name="asus_servo_asus_servo_arm_joint" type="continuous">
    <parent link="asus_servo_link"/>
    <child link="asus_servo_arm_link"/>
    <origin rpy="1.5708 1.5708 0" xyz="0 -0.042 0"/>
    <axis xyz="0 0 1"/>
  </joint>
  <joint name="asus_servo_arm_asus_mount_joint" type="fixed">
    <parent link="asus_servo_arm_link"/>
    <child link="asus_mount_link"/>
    <origin rpy="1.5708 0 1.5708" xyz="0 -0.053 -0.016"/>
  </joint>
  <link name="creative_mount_link">
    <visual>
      <origin rpy="0 0 0" xyz="0 0 0"/>
      <geometry>
        <mesh filename="package://carl_description/meshes/creative_mount.min.dae"/>
      </geometry>
    </visual>
  </link>
  <link name="creative_servo_link">
    <visual>
      <origin rpy="0 0 0" xyz="0 0 0"/>
      <geometry>
        <mesh filename="package://carl_description/meshes/servo.min.dae"/>
      </geometry>
    </visual>
    <collision>
      <origin rpy="0 0 0" xyz="0.01 -0.021 0"/>
      <geometry>
        <box size="0.06 0.05 0.035"/>
      </geometry>
    </collision>
  </link>
  <link name="creative_servo_arm_link">
    <visual>
      <origin rpy="0 0 0" xyz="0 0 0"/>
      <geometry>
        <mesh filename="package://carl_description/meshes/servo_arm.min.dae"/>
      </geometry>
    </visual>
    <collision>
      <origin rpy="0 0 0" xyz="0 -0.01 -0.02"/>
      <geometry>
        <box size="0.035 0.09 0.06"/>
      </geometry>
    </collision>
  </link>
  <link name="creative_plate_link">
    <visual>
      <origin rpy="0 0 0" xyz="0 0 0"/>
      <geometry>
        <mesh filename="package://carl_description/meshes/creative_plate.min.dae"/>
      </geometry>
    </visual>
  </link>
  <joint name="creative_plate_link_creative_camera_joint" type="fixed">
    <origin rpy="0 0 0" xyz="0 0.0 0.012"/>
    <parent link="creative_plate_link"/>
    <child link="creative_camera_link"/>
  </joint>
  <link name="creative_camera_link">
    <visual>
      <origin rpy="0 0 0" xyz="0 0 0"/>
      <geometry>
        <mesh filename="package://carl_description/meshes/creative_camera.min.dae"/>
      </geometry>
    </visual>
    <collision>
      <origin rpy="0 0 1.5708" xyz="0.0 0.0 0.0"/>
      <geometry>
        <box size="0.04 .14 0.04"/>
      </geometry>
    </collision>
  </link>
  <joint name="top_plate_creative_mount_joint" type="fixed">
    <parent link="top_plate_link"/>
    <child link="creative_mount_link"/>
    <origin rpy="0 0 3.1415926536" xyz="0.07 0 -0.03"/>
  </joint>
  <joint name="creative_servo_mount_creative_servo_joint" type="fixed">
    <parent link="creative_mount_link"/>
    <child link="creative_servo_link"/>
    <origin rpy="1.5708 -0.349065 0" xyz="-0.023 0 -0.01"/>
    <!--20 degrees -->
  </joint>
  <joint name="creative_servo_creative_servo_arm_joint" type="continuous">
    <parent link="creative_servo_link"/>
    <child link="creative_servo_arm_link"/>
    <origin rpy="1.5708 1.5708 0" xyz="0 -0.042 0"/>
    <axis xyz="0 0 1"/>
  </joint>
  <joint name="creative_servo_arm_creative_plate_joint" type="fixed">
    <parent link="creative_servo_arm_link"/>
    <child link="creative_plate_link"/>
    <origin rpy="1.5708 1.5708 0" xyz="0 -0.057 -0.024"/>
  </joint>
  <joint name="right_rear_strut_link_right_side_cover_joint" type="fixed">
    <origin rpy="0 0 0" xyz="-0.229 -0.026 0.447"/>
    <parent link="right_rear_strut_link"/>
    <child link="right_side_cover_link"/>
  </joint>
  <link name="right_side_cover_link">
    <visual>
      <origin rpy="0 0 1.5708" xyz="0 0 0"/>
      <geometry>
        <mesh filename="package://carl_description/meshes/side_cover.min.dae"/>
      </geometry>
    </visual>
  </link>
  <joint name="left_rear_strut_link_left_side_cover_joint" type="fixed">
    <origin rpy="0 0 0" xyz="0.229 0.026 0.447"/>
    <parent link="left_rear_strut_link"/>
    <child link="left_side_cover_link"/>
  </joint>
  <link name="left_side_cover_link">
    <visual>
      <origin rpy="0 0 1.5708" xyz="0 0 0"/>
      <geometry>
        <mesh filename="package://carl_description/meshes/side_cover.min.dae"/>
      </geometry>
    </visual>
  </link>
  <joint name="base_front_cover_joint" type="fixed">
    <parent link="base_link"/>
    <child link="FrontCover_link"/>
    <origin rpy="0 0 0" xyz=".247 0 0.242"/>
  </joint>
  <joint name="base_back_cover" type="fixed">
    <parent link="base_link"/>
    <child link="BackCover_link"/>
    <origin rpy="0 0 0" xyz="-.237 0 -0.102"/>
  </joint>
  <link name="FrontCover_link">
    <visual>
      <origin rpy="0 0 1.5708" xyz="0 0 0"/>
      <geometry>
        <mesh filename="package://carl_description/meshes/front_cover.min.dae"/>
      </geometry>
    </visual>
    <collision>
      <origin rpy="0 0 0" xyz="-.245 0 -.241"/>
      <geometry>
        <mesh filename="package://carl_description/meshes/front_cover_collision.stl"/>
      </geometry>
    </collision>
  </link>
  <link name="BackCover_link">
    <visual>
      <origin rpy="0 0 0" xyz="0 0 0"/>
      <geometry>
        <!--<box size="0.005 0.45 0.6" />-->
        <mesh filename="package://carl_description/meshes/back_cover.min.dae"/>
      </geometry>
    </visual>
  </link>
  <link name="base_footprint"/>
  <link name="base_link">
    <visual>
      <origin rpy="0 0 0" xyz="0 0 0"/>
      <geometry>
        <mesh filename="package://carl_description/meshes/base.min.dae"/>
      </geometry>
    </visual>
  </link>
  <joint name="base_footprint_base_link_joint" type="fixed">
    <parent link="base_footprint"/>
    <child link="base_link"/>
    <origin rpy="0 0 0" xyz="0 0 0.23114"/>
  </joint>
  <joint name="base_link_left_wheel_joint" type="continuous">
    <origin rpy="-1.5708 0 0" xyz="0 0.25 0"/>
    <axis xyz="0 0 1"/>
    <parent link="base_link"/>
    <child link="left_wheel_link"/>
  </joint>
  <link name="left_wheel_link">
    <visual>
      <origin rpy="0 0 0" xyz="0 0 0"/>
      <geometry>
        <mesh filename="package://carl_description/meshes/wheel.min.dae"/>
      </geometry>
    </visual>
    <collision>
      <origin rpy="0 0 0" xyz="0 0 .025"/>
      <geometry>
        <cylinder length="0.1" radius="0.25"/>
      </geometry>
    </collision>
  </link>
  <joint name="base_link_right_wheel_joint" type="continuous">
    <origin rpy="1.5708 0 0" xyz="0 -0.25 0"/>
    <axis xyz="0 0 1"/>
    <parent link="base_link"/>
    <child link="right_wheel_link"/>
  </joint>
  <link name="right_wheel_link">
    <visual>
      <origin rpy="0 0 0" xyz="0 0 0"/>
      <geometry>
        <mesh filename="package://carl_description/meshes/wheel.min.dae"/>
      </geometry>
    </visual>
    <collision>
      <origin rpy="0 0 0" xyz="0 0 .025"/>
      <geometry>
        <cylinder length="0.1" radius="0.25"/>
      </geometry>
    </collision>
  </link>
  <joint name="base_link_caster_plate_joint" type="fixed">
    <origin rpy="0 0 0" xyz="0.2883 0 0"/>
    <parent link="base_link"/>
    <child link="caster_plate_link"/>
  </joint>
  <joint name="caster_plate__caster_joint" type="continuous">
    <parent link="caster_plate_link"/>
    <child link="caster_link"/>
    <origin rpy="0 0 0" xyz="0.0267 0 -0.024"/>
    <axis xyz="0 0 1"/>
  </joint>
  <link name="caster_plate_link">
    <visual>
      <origin rpy="0 0 1.5708" xyz="0 0 0"/>
      <geometry>
        <mesh filename="package://carl_description/meshes/caster_plate.min.dae"/>
      </geometry>
    </visual>
  </link>
  <link name="caster_link">
    <visual>
      <origin rpy="0 0 0" xyz="0 0 0"/>
      <geometry>
        <mesh filename="package://carl_description/meshes/caster.min.dae"/>
      </geometry>
    </visual>
    <collision>
      <origin rpy="0 0 0" xyz="0 0 -0.09"/>
      <geometry>
        <cylinder length="0.213" radius="0.116"/>
      </geometry>
    </collision>
  </link>
  <joint name="caster_plate_link_hokuyo_joint" type="fixed">
    <origin rpy="0 0 0" xyz="0.07 0 0.035"/>
    <parent link="caster_plate_link"/>
    <child link="hokuyo_link"/>
  </joint>
  <link name="hokuyo_link">
    <visual>
      <origin rpy="0 0 0" xyz="0 0 0"/>
      <geometry>
        <mesh filename="package://carl_description/meshes/hokuyo.min.dae"/>
      </geometry>
    </visual>
  </link>
  <link name="jaco_link_base">
    <visual>
      <geometry>
        <mesh filename="package://jaco_description/meshes/jaco_link_base.min.dae"/>
      </geometry>
      <material name="carbon_fiber">
        <color rgba="0.792156862745098 0.819607843137255 0.933333333333333 1"/>
      </material>
    </visual>
    <collision>
      <geometry>
        <mesh filename="package://jaco_description/meshes/jaco_link_base.min.dae"/>
      </geometry>
    </collision>
  </link>
  <joint name="jaco_joint_base" type="fixed">
    <parent link="jaco_mount_link"/>
    <child link="jaco_link_base"/>
    <axis xyz="0 0 0"/>
    <origin rpy="0 0 0" xyz="0 0 0"/>
    <limit effort="30" lower="-6.28318530718" upper="6.28318530718" velocity="5"/>
  </joint>
  <link name="jaco_link_1">
    <visual>
      <geometry>
        <mesh filename="package://jaco_description/meshes/jaco_link_1.min.dae"/>
      </geometry>
      <material name="carbon_fiber">
        <color rgba="0.792156862745098 0.819607843137255 0.933333333333333 1"/>
      </material>
    </visual>
    <collision>
      <geometry>
        <mesh filename="package://jaco_description/meshes/jaco_link_1.min.dae"/>
      </geometry>
    </collision>
  </link>
  <joint name="jaco_joint_1" type="revolute">
    <parent link="jaco_link_base"/>
    <child link="jaco_link_1"/>
    <axis xyz="0 0 1"/>
    <origin rpy="3.14159265359 0 0" xyz="0 0 0.1535"/>
    <limit effort="30" lower="-6.28318530718" upper="6.28318530718" velocity="5"/>
  </joint>
  <link name="jaco_link_2">
    <visual>
      <geometry>
        <mesh filename="package://jaco_description/meshes/jaco_link_2.min.dae"/>
      </geometry>
      <material name="carbon_fiber">
        <color rgba="0.792156862745098 0.819607843137255 0.933333333333333 1"/>
      </material>
    </visual>
    <collision>
      <geometry>
        <mesh filename="package://jaco_description/meshes/jaco_link_2.min.dae"/>
      </geometry>
    </collision>
  </link>
  <joint name="jaco_joint_2" type="revolute">
    <parent link="jaco_link_1"/>
    <child link="jaco_link_2"/>
    <axis xyz="0 0 1"/>
    <origin rpy="-1.57079632679 -1.57079632679 0" xyz="0 0 -0.1185"/>
    <limit effort="30" lower="0" upper="6.28318530718" velocity="5"/>
  </joint>
  <link name="jaco_link_3">
    <visual>
      <geometry>
        <mesh filename="package://jaco_description/meshes/jaco_link_3.min.dae"/>
      </geometry>
      <material name="carbon_fiber">
        <color rgba="0.792156862745098 0.819607843137255 0.933333333333333 1"/>
      </material>
    </visual>
    <collision>
      <geometry>
        <mesh filename="package://jaco_description/meshes/jaco_link_3.min.dae"/>
      </geometry>
    </collision>
  </link>
  <joint name="jaco_joint_3" type="revolute">
    <parent link="jaco_link_2"/>
    <child link="jaco_link_3"/>
    <axis xyz="0 0 1"/>
    <origin rpy="3.14159265359 0 3.14159265359" xyz="0.41 0 0"/>
    <limit effort="30" lower="0" upper="6.28318530718" velocity="5"/>
  </joint>
  <link name="jaco_link_4">
    <visual>
      <geometry>
        <mesh filename="package://jaco_description/meshes/jaco_link_4_5.min.dae"/>
      </geometry>
      <material name="carbon_fiber">
        <color rgba="0.792156862745098 0.819607843137255 0.933333333333333 1"/>
      </material>
    </visual>
    <collision>
      <geometry>
        <mesh filename="package://jaco_description/meshes/jaco_link_4_5.min.dae"/>
      </geometry>
    </collision>
  </link>
  <joint name="jaco_joint_4" type="revolute">
    <parent link="jaco_link_3"/>
    <child link="jaco_link_4"/>
    <axis xyz="0 0 1"/>
    <origin rpy="0 -1.57079632679 0" xyz="0.207 0 -0.01125"/>
    <limit effort="30" lower="-6.28318530718" upper="6.28318530718" velocity="5"/>
  </joint>
  <link name="jaco_link_5">
    <visual>
      <geometry>
        <mesh filename="package://jaco_description/meshes/jaco_link_4_5.min.dae"/>
      </geometry>
      <material name="carbon_fiber">
        <color rgba="0.792156862745098 0.819607843137255 0.933333333333333 1"/>
      </material>
    </visual>
    <collision>
      <geometry>
        <mesh filename="package://jaco_description/meshes/jaco_link_4_5.min.dae"/>
      </geometry>
    </collision>
  </link>
  <joint name="jaco_joint_5" type="revolute">
    <parent link="jaco_link_4"/>
    <child link="jaco_link_5"/>
    <axis xyz="0 0 1"/>
    <origin rpy="0 0.959931088597 3.14159265359" xyz="0.0343 0 -0.06588"/>
    <limit effort="30" lower="-6.28318530718" upper="6.28318530718" velocity="5"/>
  </joint>
  <link name="jaco_link_hand">
    <visual>
      <geometry>
        <mesh filename="package://jaco_description/meshes/jaco_link_hand.min.dae"/>
      </geometry>
      <material name="carbon_fiber">
        <color rgba="0.792156862745098 0.819607843137255 0.933333333333333 1"/>
      </material>
    </visual>
    <collision>
      <geometry>
        <mesh filename="package://jaco_description/meshes/jaco_link_hand.min.dae"/>
      </geometry>
    </collision>
  </link>
  <joint name="jaco_joint_6" type="revolute">
    <parent link="jaco_link_5"/>
    <child link="jaco_link_hand"/>
    <axis xyz="0 0 1"/>
    <origin rpy="0 0.959931088597 3.14159265359" xyz="0.0343 0 -0.06588"/>
    <limit effort="30" lower="-6.28318530718" upper="6.28318530718" velocity="5"/>
  </joint>
  <link name="jaco_large_ring_cover_1">
    <visual>
      <geometry>
        <mesh filename="package://jaco_description/meshes/jaco_large_ring_cover.min.dae"/>
      </geometry>
      <material name="carbon_fiber">
        <color rgba="0.792156862745098 0.819607843137255 0.933333333333333 1"/>
      </material>
    </visual>
    <collision>
      <geometry>
        <mesh filename="package://jaco_description/meshes/jaco_large_ring_cover.min.dae"/>
      </geometry>
    </collision>
  </link>
  <joint name="jaco_large_ring_cover_1_joint" type="fixed">
    <parent link="jaco_link_base"/>
    <child link="jaco_large_ring_cover_1"/>
    <axis xyz="0 0 1"/>
    <origin rpy="3.14159265359 0 0" xyz="0 0 0.1535"/>
    <limit effort="30" lower="-6.28318530718" upper="6.28318530718" velocity="5"/>
  </joint>
  <link name="jaco_large_ring_cover_2">
    <visual>
      <geometry>
        <mesh filename="package://jaco_description/meshes/jaco_large_ring_cover.min.dae"/>
      </geometry>
      <material name="carbon_fiber">
        <color rgba="0.792156862745098 0.819607843137255 0.933333333333333 1"/>
      </material>
    </visual>
    <collision>
      <geometry>
        <mesh filename="package://jaco_description/meshes/jaco_large_ring_cover.min.dae"/>
      </geometry>
    </collision>
  </link>
  <joint name="jaco_large_ring_cover_2_joint" type="fixed">
    <parent link="jaco_link_1"/>
    <child link="jaco_large_ring_cover_2"/>
    <axis xyz="0 0 1"/>
    <origin rpy="-1.57079632679 -1.57079632679 0" xyz="0 0 -0.1185"/>
    <limit effort="30" lower="0" upper="6.28318530718" velocity="5"/>
  </joint>
  <link name="jaco_large_ring_cover_3">
    <visual>
      <geometry>
        <mesh filename="package://jaco_description/meshes/jaco_large_ring_cover.min.dae"/>
      </geometry>
      <material name="carbon_fiber">
        <color rgba="0.792156862745098 0.819607843137255 0.933333333333333 1"/>
      </material>
    </visual>
    <collision>
      <geometry>
        <mesh filename="package://jaco_description/meshes/jaco_large_ring_cover.min.dae"/>
      </geometry>
    </collision>
  </link>
  <joint name="jaco_large_ring_cover_3_joint" type="fixed">
    <parent link="jaco_link_2"/>
    <child link="jaco_large_ring_cover_3"/>
    <axis xyz="0 0 1"/>
    <origin rpy="3.14159265359 0 3.14159265359" xyz="0.41 0 0"/>
    <limit effort="30" lower="0" upper="6.28318530718" velocity="5"/>
  </joint>
  <link name="jaco_small_ring_cover_1">
    <visual>
      <geometry>
        <mesh filename="package://jaco_description/meshes/jaco_small_ring_cover.min.dae"/>
      </geometry>
      <material name="carbon_fiber">
        <color rgba="0.792156862745098 0.819607843137255 0.933333333333333 1"/>
      </material>
    </visual>
    <collision>
      <geometry>
        <mesh filename="package://jaco_description/meshes/jaco_small_ring_cover.min.dae"/>
      </geometry>
    </collision>
  </link>
  <joint name="jaco_large_ring_cover_4_joint" type="fixed">
    <parent link="jaco_link_3"/>
    <child link="jaco_small_ring_cover_1"/>
    <axis xyz="0 0 1"/>
    <origin rpy="0 -1.57079632679 0" xyz="0.207 0 -0.01125"/>
    <limit effort="30" lower="-6.28318530718" upper="6.28318530718" velocity="5"/>
  </joint>
  <link name="jaco_small_ring_cover_2">
    <visual>
      <geometry>
        <mesh filename="package://jaco_description/meshes/jaco_small_ring_cover.min.dae"/>
      </geometry>
      <material name="carbon_fiber">
        <color rgba="0.792156862745098 0.819607843137255 0.933333333333333 1"/>
      </material>
    </visual>
    <collision>
      <geometry>
        <mesh filename="package://jaco_description/meshes/jaco_small_ring_cover.min.dae"/>
      </geometry>
    </collision>
  </link>
  <joint name="jaco_large_ring_cover_5_joint" type="fixed">
    <parent link="jaco_link_4"/>
    <child link="jaco_small_ring_cover_2"/>
    <axis xyz="0 0 1"/>
    <origin rpy="0 0.959931088597 3.14159265359" xyz="0.0343 0 -0.06588"/>
    <limit effort="30" lower="-6.28318530718" upper="6.28318530718" velocity="5"/>
  </joint>
  <link name="jaco_small_ring_cover_3">
    <visual>
      <geometry>
        <mesh filename="package://jaco_description/meshes/jaco_small_ring_cover.min.dae"/>
      </geometry>
      <material name="carbon_fiber">
        <color rgba="0.792156862745098 0.819607843137255 0.933333333333333 1"/>
      </material>
    </visual>
    <collision>
      <geometry>
        <mesh filename="package://jaco_description/meshes/jaco_small_ring_cover.min.dae"/>
      </geometry>
    </collision>
  </link>
  <joint name="jaco_large_ring_cover_6_joint" type="fixed">
    <parent link="jaco_link_4"/>
    <child link="jaco_small_ring_cover_3"/>
    <axis xyz="0 0 1"/>
    <origin rpy="0 0.959931088597 3.14159265359" xyz="0.0343 0 -0.06588"/>
    <limit effort="30" lower="-6.28318530718" upper="6.28318530718" velocity="5"/>
  </joint>
  <link name="jaco_link_finger_1">
    <visual>
      <geometry>
        <mesh filename="package://jaco_description/meshes/jaco_link_finger.min.dae"/>
      </geometry>
      <material name="carbon_fiber">
        <color rgba="0.792156862745098 0.819607843137255 0.933333333333333 1"/>
      </material>
    </visual>
    <collision>
      <geometry>
        <mesh filename="package://jaco_description/meshes/jaco_link_finger.min.dae"/>
      </geometry>
    </collision>
  </link>
  <joint name="jaco_joint_finger_1" type="revolute">
    <parent link="jaco_link_hand"/>
    <child link="jaco_link_finger_1"/>
    <axis xyz="0 0 1"/>
    <origin rpy="-1.7983 1.117 3.1416" xyz="-0.032578 0.0033 -0.12131"/>
    <limit effort="30" lower="0" upper="0.698131700798" velocity="5"/>
  </joint>
  <link name="jaco_link_finger_2">
    <visual>
      <geometry>
        <mesh filename="package://jaco_description/meshes/jaco_link_finger.min.dae"/>
      </geometry>
      <material name="carbon_fiber">
        <color rgba="0.792156862745098 0.819607843137255 0.933333333333333 1"/>
      </material>
    </visual>
    <collision>
      <geometry>
        <mesh filename="package://jaco_description/meshes/jaco_link_finger.min.dae"/>
      </geometry>
    </collision>
  </link>
  <joint name="jaco_joint_finger_2" type="revolute">
    <parent link="jaco_link_hand"/>
    <child link="jaco_link_finger_2"/>
    <axis xyz="0 0 1"/>
    <origin rpy="-1.5161 1.1459 0.23978" xyz="0.027788 0.0206 -0.12131"/>
    <limit effort="30" lower="0" upper="0.698131700798" velocity="5"/>
  </joint>
  <link name="jaco_link_finger_3">
    <visual>
      <geometry>
        <mesh filename="package://jaco_description/meshes/jaco_link_finger.min.dae"/>
      </geometry>
      <material name="carbon_fiber">
        <color rgba="0.792156862745098 0.819607843137255 0.933333333333333 1"/>
      </material>
    </visual>
    <collision>
      <geometry>
        <mesh filename="package://jaco_description/meshes/jaco_link_finger.min.dae"/>
      </geometry>
    </collision>
  </link>
  <joint name="jaco_joint_finger_3" type="revolute">
    <parent link="jaco_link_hand"/>
    <child link="jaco_link_finger_3"/>
    <axis xyz="0 0 1"/>
    <origin rpy="-1.6222 1.117 -0.23615" xyz="0.027788 -0.0206 -0.12131"/>
    <limit effort="30" lower="0" upper="0.698131700798" velocity="5"/>
  </joint>
  <link name="jaco_link_finger_tip_1">
    <visual>
      <geometry>
        <mesh filename="package://jaco_description/meshes/jaco_link_finger_tip.min.dae"/>
      </geometry>
      <material name="carbon_fiber">
        <color rgba="0.792156862745098 0.819607843137255 0.933333333333333 1"/>
      </material>
    </visual>
    <collision>
      <geometry>
        <mesh filename="package://jaco_description/meshes/jaco_link_finger_tip.min.dae"/>
      </geometry>
    </collision>
  </link>
  <joint name="jaco_joint_finger_tip_1" type="revolute">
    <parent link="jaco_link_finger_1"/>
    <child link="jaco_link_finger_tip_1"/>
    <axis xyz="0 0 1"/>
    <origin rpy="0 0 0" xyz="0.044094 -0.0029 0"/>
    <limit effort="30" lower="0" upper="0.698131700798" velocity="5"/>
  </joint>
  <link name="jaco_link_finger_tip_2">
    <visual>
      <geometry>
        <mesh filename="package://jaco_description/meshes/jaco_link_finger_tip.min.dae"/>
      </geometry>
      <material name="carbon_fiber">
        <color rgba="0.792156862745098 0.819607843137255 0.933333333333333 1"/>
      </material>
    </visual>
    <collision>
      <geometry>
        <mesh filename="package://jaco_description/meshes/jaco_link_finger_tip.min.dae"/>
      </geometry>
    </collision>
  </link>
  <joint name="jaco_joint_finger_tip_2" type="revolute">
    <parent link="jaco_link_finger_2"/>
    <child link="jaco_link_finger_tip_2"/>
    <axis xyz="0 0 1"/>
    <origin rpy="0 0 0" xyz="0.044094 -0.0029 0"/>
    <limit effort="30" lower="0" upper="0.698131700798" velocity="5"/>
  </joint>
  <link name="jaco_link_finger_tip_3">
    <visual>
      <geometry>
        <mesh filename="package://jaco_description/meshes/jaco_link_finger_tip.min.dae"/>
      </geometry>
      <material name="carbon_fiber">
        <color rgba="0.792156862745098 0.819607843137255 0.933333333333333 1"/>
      </material>
    </visual>
    <collision>
      <geometry>
        <mesh filename="package://jaco_description/meshes/jaco_link_finger_tip.min.dae"/>
      </geometry>
    </collision>
  </link>
  <joint name="jaco_joint_finger_tip_3" type="revolute">
    <parent link="jaco_link_finger_3"/>
    <child link="jaco_link_finger_tip_3"/>
    <axis xyz="0 0 1"/>
    <origin rpy="0 0 0" xyz="0.044094 -0.0029 0"/>
    <limit effort="30" lower="0" upper="0.698131700798" velocity="5"/>
  </joint>
</robot>

