<?xml version="1.0"?>
<robot xmlns:sensor="http://playerstage.sourceforge.net/gazebo/xmlschema/#sensor"
       xmlns:controller="http://playerstage.sourceforge.net/gazebo/xmlschema/#controller"
       xmlns:interface="http://playerstage.sourceforge.net/gazebo/xmlschema/#interface"
       xmlns:xacro="http://ros.org/wiki/xacro">

  <xacro:include filename="$(find carl_description)/urdf/sensors/creative_camera.urdf.xacro" />

  <xacro:macro name="carl_creative_camera_mount">
    <link name="creative_mount_link">
      <visual>
        <origin xyz="0 0 0" rpy="0 0 0" />
        <geometry>
          <mesh filename="package://carl_description/meshes/creative_mount.min.dae" />
        </geometry>
      </visual>
    </link>
    
    <link name="creative_servo_link">
      <visual>
        <origin xyz="0 0 0" rpy="0 0 0" />
        <geometry>
          <mesh filename="package://carl_description/meshes/servo.min.dae" />
        </geometry>
      </visual>
	  <collision>
        <origin xyz="0.01 -0.021 0" rpy="0 0 0" />
        <geometry>
          <box size="0.06 0.05 0.035" />
         </geometry>
      </collision>
    </link>
            
    <link name="creative_servo_arm_link">
      <visual>
        <origin xyz="0 0 0" rpy="0 0 0" />
        <geometry>
          <mesh filename="package://carl_description/meshes/servo_arm.min.dae" />
        </geometry>
      </visual>
	  <collision>
        <origin xyz="0 -0.01 -0.02" rpy="0 0 0" />
        <geometry>
          <box size="0.035 0.09 0.06" />
         </geometry>
      </collision>
    </link>
    
    <link name="creative_plate_link">
      <visual>
        <origin xyz="0 0 0" rpy="0 0 0" />
        <geometry>
          <mesh filename="package://carl_description/meshes/creative_plate.min.dae" />
        </geometry>
      </visual>
    </link>
    
    <xacro:sensor_creative_camera parent="creative_plate_link">
      <origin xyz="0 0.0 0.012" rpy="0 0 0" />
    </xacro:sensor_creative_camera>	
    
    <joint name="top_plate_creative_mount_joint" type="fixed">
      <parent link="top_plate_link" />
      <child link="creative_mount_link" />
      <origin xyz="0.07 0 -0.03" rpy="0 0 3.1415926536" />
    </joint>
    
    <joint name="creative_servo_mount_creative_servo_joint" type="fixed">
      <parent link="creative_mount_link" />
      <child link="creative_servo_link" />      
      <origin xyz="-0.023 0 -0.01" rpy="1.5708 -0.349065 0" /> <!--20 degrees -->
    </joint>
  
    <joint name="creative_servo_creative_servo_arm_joint" type="continuous">
      <parent link="creative_servo_link" />
      <child link="creative_servo_arm_link" />
      <origin xyz="0 -0.042 0" rpy="1.5708 1.5708 0" />
      <axis xyz="0 0 1" />
    </joint>
    
    <joint name="creative_servo_arm_creative_plate_joint" type="fixed">
      <parent link="creative_servo_arm_link" />
      <child link="creative_plate_link" />
      <origin xyz="0 -0.057 -0.024" rpy="1.5708 1.5708 0" />
    </joint>
    
  </xacro:macro>
</robot>
