<?xml version="1.0"?>

<robot xmlns:sensor="http://playerstage.sourceforge.net/gazebo/xmlschema/#sensor"
        xmlns:controller="http://playerstage.sourceforge.net/gazebo/xmlschema/#controller"
        xmlns:interface="http://playerstage.sourceforge.net/gazebo/xmlschema/#interface"
        xmlns:xacro="http://ros.org/wiki/xacro">
        
<xacro:include filename="$(find carl_description)/urdf/components/carl_wheel.urdf.xacro" />
<xacro:include filename="$(find carl_description)/urdf/components/carl_rear_strut.urdf.xacro" />
<xacro:include filename="$(find carl_description)/urdf/components/carl_caster_assembly.urdf.xacro" />


<xacro:macro name="carl_base" params="name">
  
  <link name="${name}_link">
   <visual>
      <origin xyz="0 0 0" rpy="0 0 0"/>    
      <geometry>
        <mesh filename="package://carl_description/meshes/base.dae" />
      </geometry>
    </visual>
  </link>
      
  <link name="TopPlate_link">
    <visual>
      <origin xyz="0 0 0" rpy="0 0 -1.5708" />
      <geometry>
        <mesh filename="package://carl_description/meshes/table_plate.dae" />
      </geometry>
    </visual>
    <collision>
      <origin xyz="-.29 0 -0.299" rpy="0 0 0" />
      <geometry>
        <box size="0.495 0.59 0.65" />
      </geometry>
    </collision>
  </link>
  
  <link name="CameraLift_link">
    <visual>
      <origin xyz="0 0 0" rpy="0 0 1.5708" />
      <geometry>
        <mesh filename="package://carl_description/meshes/camera_lift.dae" />
      </geometry>
    </visual>
    <collision>
      <origin xyz="0 0 0" rpy="0 0 1.5708" />
      <geometry>
        <mesh filename="package://carl_description/meshes/camera_lift.dae" />
      </geometry>
    </collision>
  </link>
  
  <link name="CameraTiltBracket_link">
	<!--exists to move center of rotation for camera mount-->
  </link>
  
  <link name="CameraTiltPlate_link">
    <visual>
      <origin xyz="0 0 0" rpy="0 1.5708 0" />
      <geometry>
        <mesh filename="package://carl_description/meshes/camera_plate.dae" />
      </geometry>
    </visual>
    <collision>
      <origin xyz="0 0 0" rpy="0 1.5708 0" />
      <geometry>
        <mesh filename="package://carl_description/meshes/camera_plate.dae" />
      </geometry>
    </collision>
  </link>
  
  <link name="JacoMount_link">
    <visual>      
      <origin xyz="0 0 0" rpy="0 0 1.5708" />
      <geometry>
        <mesh filename="package://carl_description/meshes/jaco_mount.dae" />
      </geometry>
    </visual>
  </link>

  <link name="Hokuyo_link">
    <visual>
      <origin xyz="0 0 0" rpy="0 0 0" />
      <geometry>
        <mesh filename="package://carl_description/meshes/hokuyo.dae" />
      </geometry>
    </visual>
  </link>
 
   <link name="LeftSideCover_link">
    <visual>
      <origin xyz="0 0 0" rpy="0 0 1.5708" />
      <geometry>
        <mesh filename="package://carl_description/meshes/side_cover.dae" />
      </geometry>
    </visual>
  </link>

   <link name="RightSideCover_link">
    <visual>
      <origin xyz="0 0 0" rpy="0 0 1.5708" />
      <geometry>
        <mesh filename="package://carl_description/meshes/side_cover.dae" />
      </geometry>
    </visual>
  </link>
  
  <link name="FrontCover_link">
    <visual>
      <origin xyz="0 0 0" rpy="0 0 1.5708" />
      <geometry>
        <mesh filename="package://carl_description/meshes/front_cover.dae" />
      </geometry>
    </visual>
    <collision>
      <origin xyz="-.245 0 -.241" rpy="0 0 0" />
      <geometry>
        <mesh filename="package://carl_description/meshes/front_cover_collision.stl" />
      </geometry>
    </collision>
  </link>
  
  <link name="BackCover_link">
    <visual>
      <origin xyz="0 0 0" rpy="0 0 0" />
      <geometry>
      	<!--<box size="0.005 0.45 0.6" />-->
      	<mesh filename="package://carl_description/meshes/back_cover.dae" />
      </geometry>
    </visual>
  </link>
  
   <!-- left wheel -->
   <xacro:carl_wheel suffix="left" parent="${name}_link">
     <origin xyz="0 0.25 0" rpy="-1.5708 0 0" />
   </xacro:carl_wheel>

   <!-- right wheel -->
   <xacro:carl_wheel suffix="right" parent="${name}_link">
     <origin xyz="0 -0.25 0" rpy="1.5708 0 0" />
   </xacro:carl_wheel>
    
   <!-- caster assembly -->
   <xacro:carl_caster_assembly parent="${name}_link">
     <origin xyz="0.2883 0 0" rpy="0 0 0" />
   </xacro:carl_caster_assembly>
  
   <!-- left rear strut -->
   <xacro:carl_rear_strut suffix="left" parent="${name}_link">
     <origin xyz="-0.222 0.200 -0.102" rpy="0 0 0" />
   </xacro:carl_rear_strut>

   <!-- right rear strut -->
   <xacro:carl_rear_strut suffix="right" parent="${name}_link">  
     <origin xyz="-0.222 -0.200 -0.102" rpy="0 0 0" />
   </xacro:carl_rear_strut>
    
  
  <joint name="RearLeftStrutToTopPlate" type="fixed">
    <parent link="right_rear_strut_link"/>
    <child link="TopPlate_link"/>
    <origin xyz="0.516 0.20 0.598" rpy="0 0 0" />
  </joint>
  
  <joint name="RearLeftStrutToCameraLift" type="fixed">
    <parent link="right_rear_strut_link"/>
    <child link="CameraLift_link"/>
    <origin xyz="0.01 0.20 1.461" rpy="0 0 0" />
  </joint>
  
    <joint name="CameraLiftToCameraTiltBracket" type="continuous">
    <parent link="CameraLift_link"/>
    <child link="CameraTiltBracket_link"/>
    <origin xyz="0.03 -0.10 0" rpy="1.5708 0 0" />
    <axis xyz="0 0 1" />
  </joint>
  
  <joint name="CameraLiftBracketToCameraTiltPlate" type="fixed">
    <parent link="CameraTiltBracket_link"/>
    <child link="CameraTiltPlate_link"/>
    <origin xyz="0.11 0 -0.10" rpy="0 0 0" />
  </joint>

  <joint name="TopPlateToJacoMount" type="fixed">
    <parent link="TopPlate_link"/>
    <child link="JacoMount_link"/>
    <origin xyz="0 0 -0.13" rpy="0 0 0" />
  </joint>

  <joint name="caster_hokuyo_joint" type="fixed">
    <parent link="caster_plate_link"/>
    <child link="Hokuyo_link"/>
    <origin xyz="0.07 0 0.035" rpy="0 0 0" />
  </joint>
  
  <joint name="left_rear_strut_left_side_cover_joint" type="fixed">
    <parent link="left_rear_strut_link"/>
    <child link="LeftSideCover_link"/>
    <origin xyz="0.229 0.026 0.447" rpy="0 0 0" />
  </joint>
  
  <joint name="right_right_strut_right_side_cover" type="fixed">
    <parent link="right_rear_strut_link"/>
    <child link="RightSideCover_link"/>
    <origin xyz="0.229 -0.026 0.447" rpy="0 0 0" />
  </joint>

  <joint name="${name}_front_cover_joint" type="fixed">
    <parent link="${name}_link"/>
    <child link="FrontCover_link"/>
    <origin xyz=".247 0 0.242" rpy="0 0 0" />
  </joint>
  
  <joint name="${name}_back_cover" type="fixed">
    <parent link="${name}_link"/>
    <child link="BackCover_link"/>
    <origin xyz="-.237 0 -0.102" rpy="0 0 0" />
  </joint>

</xacro:macro>

</robot>