<?xml version="1.0"?>
<robot xmlns:sensor="http://playerstage.sourceforge.net/gazebo/xmlschema/#sensor"
       xmlns:controller="http://playerstage.sourceforge.net/gazebo/xmlschema/#controller"
       xmlns:interface="http://playerstage.sourceforge.net/gazebo/xmlschema/#interface"
       xmlns:xacro="http://ros.org/wiki/xacro">

  <xacro:include filename="$(find carl_description)/urdf/sensors/asus_xtion_pro.urdf.xacro" />
  
  <xacro:macro name="carl_asus_camera_mount">
    <link name="asus_lift_link">
      <visual>
        <origin xyz="0 0 0" rpy="0 1.5708 1.5708" />
        <geometry>
          <mesh filename="package://carl_description/meshes/camera_lift.min.dae" />
        </geometry>
      </visual> 
      <collision>
        <origin xyz="0 0 0" rpy="0 1.5708 1.5708" />
        <geometry>
          <mesh filename="package://carl_description/meshes/camera_lift.min.dae" />
        </geometry>
      </collision>      
    </link>
    
    <link name="asus_mount_link">
      <visual>
        <origin xyz="0 0 0" rpy="0 1.5708 0" />
        <geometry>
          <mesh filename="package://carl_description/meshes/camera_mount.min.dae" />
        </geometry>
      </visual>
      <collision>
        <origin xyz="0 0 0" rpy="0 1.5708 0" />
        <geometry>
          <mesh filename="package://carl_description/meshes/camera_mount.min.dae" />
        </geometry>
      </collision>
    </link>
  
    <link name="asus_servo_mount_link">
      <visual>
        <origin xyz="0 0 0" rpy="0 0 0" />
        <geometry>
          <mesh filename="package://carl_description/meshes/servo_mount.min.dae" />
        </geometry>
      </visual>
      <collision>
        <origin xyz="0 0 0" rpy="0 0 0" />
        <geometry>
          <mesh filename="package://carl_description/meshes/servo_mount.min.dae" />
        </geometry>
      </collision>
    </link>
  
    <link name="asus_servo_link">
      <visual>
        <origin xyz="0 0 0" rpy="0 0 0" />
        <geometry>
          <mesh filename="package://carl_description/meshes/servo.min.dae" />
        </geometry>
      </visual>
      <collision>
        <origin xyz="0 0 0" rpy="0 0 0" />
        <geometry>
          <mesh filename="package://carl_description/meshes/servo.min.dae" />
        </geometry>
      </collision>
    </link>
        
    <link name="asus_servo_arm_link">
      <visual>
        <origin xyz="0 0 0" rpy="0 0 0" />
        <geometry>
          <mesh filename="package://carl_description/meshes/servo_arm.min.dae" />
        </geometry>
      </visual>
      <collision>
        <origin xyz="0 0 0" rpy="0 0 0" />
        <geometry>
          <mesh filename="package://carl_description/meshes/servo_arm.min.dae" />
        </geometry>
      </collision>
    </link>
    
    <xacro:sensor_asus_xtion_pro parent="asus_mount_link">
      <!-- <origin xyz="-0.016 -0.008 0.018" rpy="0 -1.5708 0" /> -->
      <origin xyz="-0.016 -0.008 0.018" rpy="0 -1.54 0" />
    </xacro:sensor_asus_xtion_pro>		
  
    <joint name="right_rear_strut_asus_lift_joint" type="fixed">
      <parent link="right_rear_strut_link" />
      <child link="asus_lift_link" />
      <origin xyz="-0.013 -0.20 1.538" rpy="0 0 3.1415926536" />
    </joint>
  
    <joint name="asus_lift_asus_servo_mount_joint" type="fixed">
      <parent link="asus_lift_link" />
      <child link="asus_servo_mount_link" />
      <origin xyz="0 0 0" rpy="1.5708 0 0" />
      <axis xyz="0 0 1" />
    </joint>
   
    <joint name="asus_servo_mount_asus_servo_joint" type="fixed">
      <parent link="asus_servo_mount_link" />
      <child link="asus_servo_link" />
      <origin xyz="0.073 0.013 0.0187" rpy="1.5708 0 3.92699" />
    </joint>
    
    <joint name="asus_servo_asus_servo_arm_joint" type="continuous">
      <parent link="asus_servo_link" />
      <child link="asus_servo_arm_link" />
      <origin xyz="0 -0.042 0" rpy="1.5708 1.5708 0" />
      <axis xyz="0 0 1" />
    </joint>
    
    <joint name="asus_servo_arm_asus_mount_joint" type="fixed">
      <parent link="asus_servo_arm_link" />
      <child link="asus_mount_link" />
      <origin xyz="0 -0.053 -0.016" rpy="1.5708 0 1.5708" />
    </joint>
  </xacro:macro>
</robot>
