<?xml version="1.0"?>

<robot xmlns:sensor="http://playerstage.sourceforge.net/gazebo/xmlschema/#sensor"
        xmlns:controller="http://playerstage.sourceforge.net/gazebo/xmlschema/#controller"
        xmlns:interface="http://playerstage.sourceforge.net/gazebo/xmlschema/#interface"
        xmlns:xacro="http://ros.org/wiki/xacro">
        
  <xacro:include filename="$(find carl_description)/urdf/sensors/asus_xtion_pro.urdf.xacro" />
  
  <xacro:macro name="carl_camera_mount">
  
    <xacro:sensor_asus_xtion_pro parent="camera_tilt_plate_link">
      <origin xyz=".025 -.02 -.02" rpy="-1.5708 0 -1.5708" />
    </xacro:sensor_asus_xtion_pro>
	
	
    <link name="camera_lift_link">
      <visual>
        <origin xyz="0 0 0" rpy="0 1.5708 1.5708" />
        <geometry>
          <mesh filename="package://carl_description/meshes/camera_lift.dae" />
        </geometry>
      </visual>
	  <collision>
        <origin xyz="0.0127 0 0" rpy="0 0 0" />
        <geometry>
          <box size="0.027 0.454 0.054" />
         </geometry>
      </collision>         
    </link>
  
    <link name="camera_tilt_bracket_link">
	  <!--exists to move center of rotation for camera mount-->
    </link>
  
    <link name="camera_tilt_plate_link">
      <visual>
        <origin xyz="0 0 0" rpy="0 1.5708 0" />
        <geometry>
          <mesh filename="package://carl_description/meshes/camera_mount.dae" />
        </geometry>
      </visual>
      <collision>
        <origin xyz="0 0 0" rpy="0 1.5708 0" />
        <geometry>
          <mesh filename="package://carl_description/meshes/camera_mount.dae" />
        </geometry>
      </collision>
    </link>
  
    <joint name="left_rear_strut_camera_lift_joint" type="fixed">
      <parent link="right_rear_strut_link"/>
      <child link="camera_lift_link"/>
      <origin xyz="0.013 0.20 1.538" rpy="0 0 0" />
    </joint>
  
    <joint name="camera_lift_camera_tilt_bracket_joint" type="continuous">
      <parent link="camera_lift_link"/>
      <child link="camera_tilt_bracket_link"/>
      <origin xyz="0.03 -0.10 0" rpy="1.5708 -1.5708 0" />
      <axis xyz="0 0 1" />
    </joint>
  
    <joint name="camera_lift_bracket_camera_tilt_plate_joint" type="fixed">
      <parent link="camera_tilt_bracket_link"/>
      <child link="camera_tilt_plate_link"/>
      <origin xyz="0.11 0 -0.10" rpy="0 0 0" />
    </joint>
  
  </xacro:macro>
</robot>
