<?xml version="1.0"?>
<robot xmlns:sensor="http://playerstage.sourceforge.net/gazebo/xmlschema/#sensor"
       xmlns:controller="http://playerstage.sourceforge.net/gazebo/xmlschema/#controller"
       xmlns:interface="http://playerstage.sourceforge.net/gazebo/xmlschema/#interface"
       xmlns:xacro="http://ros.org/wiki/xacro">
       
  <!-- Xacro properties -->
  <xacro:property name="M_SCALE" value="0.0254" />
  <xacro:property name="M_PI" value="3.1415926535897931" /> 
  <xacro:property name="M_20_DEG" value="0.34906585" /> 

  <xacro:include filename="$(find carl_description)/urdf/sensors/creative_camera.urdf.xacro" />

  <xacro:macro name="carl_creative_camera" params="parent *origin">
    <joint name="${parent}_creative_mount_link_joint" type="fixed">
      <xacro:insert_block name="origin" />
      <parent link="${parent}" />
      <child link="creative_mount_link" />
    </joint>
    <link name="creative_mount_link">
      <visual>
        <origin xyz="0 0 0" rpy="0 0 0" />
        <geometry>
          <mesh scale="${M_SCALE} ${M_SCALE} ${M_SCALE}" filename="package://carl_description/meshes/creative_mount.min.dae" />
        </geometry>
      </visual>
      <collision>
        <origin xyz="0 0 0" rpy="0 0 0" />
        <geometry>
          <mesh scale="${M_SCALE} ${M_SCALE} ${M_SCALE}" filename="package://carl_description/meshes/creative_mount.stl" />
        </geometry>
      </collision>
    </link>
    
    <joint name="creative_mount_link_creative_servo_link_joint" type="fixed">
      <parent link="creative_mount_link" />
      <child link="creative_servo_link" />      
      <origin xyz="-0.023 0 -0.01" rpy="${M_PI/2} -${M_20_DEG} 0" />
    </joint>
    <link name="creative_servo_link">
      <visual>
        <origin xyz="0 0 0" rpy="0 0 0" />
        <geometry>
          <mesh scale="${M_SCALE} ${M_SCALE} ${M_SCALE}" filename="package://carl_description/meshes/servo.min.dae" />
        </geometry>
      </visual>
      <collision>
        <origin xyz="0 0 0" rpy="0 0 0" />
        <geometry>
          <mesh scale="${M_SCALE} ${M_SCALE} ${M_SCALE}" filename="package://carl_description/meshes/servo.stl" />
        </geometry>
      </collision>
    </link>
    
    <joint name="creative_servo_link_creative_servo_arm_link_joint" type="continuous">
      <parent link="creative_servo_link" />
      <child link="creative_servo_arm_link" />
      <origin xyz="0 -0.042 0" rpy="${M_PI/2} ${M_PI/2} 0" />
      <axis xyz="0 0 1" />
    </joint>
    <link name="creative_servo_arm_link">
      <visual>
        <origin xyz="0 0 0" rpy="0 0 0" />
        <geometry>
          <mesh scale="${M_SCALE} ${M_SCALE} ${M_SCALE}" filename="package://carl_description/meshes/servo_arm.min.dae" />
        </geometry>
      </visual>
      <collision>
        <origin xyz="0 0 0" rpy="0 0 0" />
        <geometry>
          <mesh scale="${M_SCALE} ${M_SCALE} ${M_SCALE}" filename="package://carl_description/meshes/servo_arm.stl" />
        </geometry>
      </collision>
    </link>
    
    <joint name="creative_servo_arm_link_creative_plate_link_joint" type="fixed">
      <parent link="creative_servo_arm_link" />
      <child link="creative_plate_link" />
      <origin xyz="0 -0.057 -0.024" rpy="${M_PI/2} ${M_PI/2} 0" />
    </joint>
    <link name="creative_plate_link">
      <visual>
        <origin xyz="0 0 0" rpy="0 0 0" />
        <geometry>
          <mesh scale="${M_SCALE} ${M_SCALE} ${M_SCALE}" filename="package://carl_description/meshes/creative_plate.min.dae" />
        </geometry>
      </visual>
      <collision>
        <origin xyz="0 0 0" rpy="0 0 0" />
        <geometry>
          <mesh scale="${M_SCALE} ${M_SCALE} ${M_SCALE}" filename="package://carl_description/meshes/creative_plate.stl" />
        </geometry>
      </collision>
    </link>
    
    <xacro:sensor_creative_camera parent="creative_plate_link">
      <origin xyz="0 0.0 0.012" rpy="0 0 0" />
    </xacro:sensor_creative_camera>
  </xacro:macro>
</robot>
