<?xml version="1.0"?>
<robot xmlns:sensor="http://playerstage.sourceforge.net/gazebo/xmlschema/#sensor"
       xmlns:controller="http://playerstage.sourceforge.net/gazebo/xmlschema/#controller"
       xmlns:interface="http://playerstage.sourceforge.net/gazebo/xmlschema/#interface"
       xmlns:xacro="http://ros.org/wiki/xacro">
       
  <!-- Xacro properties -->
  <xacro:property name="M_SCALE" value="0.0254" />
  <xacro:property name="M_PI" value="3.1415926535897931" /> 

  <xacro:macro name="carl_caster_assembly" params="parent *origin">
    <joint name="${parent}_caster_plate_link_joint" type="fixed">
      <xacro:insert_block name="origin" />
      <parent link="${parent}" />
      <child link="caster_plate_link" />
    </joint>

    <link name="caster_plate_link">
      <visual>
        <origin xyz="0 0 0" rpy="0 0 ${M_PI/2}" />
        <geometry>
          <mesh scale="${M_SCALE} ${M_SCALE} ${M_SCALE}" filename="package://carl_description/meshes/caster_plate.min.dae" />
        </geometry>
      </visual>
      <collision>
        <origin xyz="0 0 0" rpy="0 0 ${M_PI/2}" />
        <geometry>
          <mesh scale="${M_SCALE} ${M_SCALE} ${M_SCALE}" filename="package://carl_description/meshes/caster_plate.stl" />
        </geometry>
      </collision>
    </link>

    <joint name="caster_plate_link_caster_link_joint" type="continuous">
      <parent link="caster_plate_link" />
      <child link="caster_link" />
      <origin xyz="0.0267 0 -0.024" rpy="0 0 0" />
      <axis xyz="0 0 1" />
    </joint>

    <link name="caster_link">
      <visual>
        <origin xyz="0 0 0" rpy="0 0 0" />
        <geometry>
          <mesh scale="${M_SCALE} ${M_SCALE} ${M_SCALE}" filename="package://carl_description/meshes/caster.min.dae" />
        </geometry>
      </visual>
      <collision>
        <origin xyz="0 0 0" rpy="0 0 0" />
        <geometry>
          <mesh scale="${M_SCALE} ${M_SCALE} ${M_SCALE}" filename="package://carl_description/meshes/caster.stl" />
        </geometry>
      </collision>
    </link>    
  </xacro:macro>
  
</robot>
