<?xml version="1.0"?>
<robot xmlns:sensor="http://playerstage.sourceforge.net/gazebo/xmlschema/#sensor"
       xmlns:controller="http://playerstage.sourceforge.net/gazebo/xmlschema/#controller"
       xmlns:interface="http://playerstage.sourceforge.net/gazebo/xmlschema/#interface"
       xmlns:xacro="http://ros.org/wiki/xacro">
       
  <!-- Xacro properties -->
  <xacro:property name="M_SCALE" value="0.0254" />
  <xacro:property name="M_PI" value="3.1415926535897931" /> 
       
  <xacro:macro name="carl_rear_strut" params="prefix parent *origin">
    <!-- Bottom -->
    <joint name="${parent}_${prefix}_rear_strut_joint" type="fixed">
      <xacro:insert_block name="origin" />
      <parent link="${parent}" />
      <child link="${prefix}_rear_strut_link" />
    </joint>   
    <link name="${prefix}_rear_strut_link">
      <visual>
        <origin xyz="0 0 0" rpy="0 0 -${M_PI/2}" />
        <geometry>
          <mesh scale="${M_SCALE} ${M_SCALE} ${M_SCALE}" filename="package://carl_description/meshes/rear_strut.min.dae" />
        </geometry>
      </visual>
      <collision>
        <origin xyz="0 0.001 0.525" rpy="0 0 0"/>
        <geometry>
          <box size="0.04 0.052 1.07 "/>
        </geometry>
      </collision>
    </link>
    
    <!-- Top -->
    <joint name="${prefix}_rear_strut_link_${prefix}_rear_strut_top_link_joint" type="revolute">
      <axis xyz="0 1 0" />
      <limit effort="100" velocity="20" lower="-.5236" upper=".5236" />
      <parent link="${prefix}_rear_strut_link" />
      <child link="${prefix}_rear_strut_top_link" />
      <origin xyz="0 0.001 1.055" rpy="0 0 0" />
    </joint>
    <link name="${prefix}_rear_strut_top_link">
      <visual>
        <origin xyz="0 0 0" rpy="0 0 -${M_PI/2}" />
        <geometry>
          <mesh scale="${M_SCALE} ${M_SCALE} ${M_SCALE}" filename="package://carl_description/meshes/rear_strut_top.min.dae" />
        </geometry>
      </visual>
      <collision>
        <origin xyz="-0 0 0.229" rpy="0 0 0" />
        <geometry>
          <box size="0.04 0.051 0.4572"/>
        </geometry>
      </collision>    
    </link>
  </xacro:macro>
  
</robot>